Workbook

Sheet Stats
A1: Week | B1: Day | C1: Date | D1: Time | E1: Home/Away | F1: Winner/tie | G1: Home/Away | H1: Loser/tie | I1: PtsW | J1: PtsL | K1: YdsW | L1: TOW | M1: YdsL | N1: TOL
A2: 1 | B2: Thu | C2: 44448 | D2: 8:20PM | E2: H | F2: Tampa Bay Buccaneers | G2: V | H2: Dallas Cowboys | I2: 31 | J2: 29 | K2: 431 | L2: 4 | M2: 451 | N2: 1 | O2: =I2-J2 -> 2
A3: 1 | B3: Sun | C3: 44451 | D3: 1:00PM | E3: V | F3: Philadelphia Eagles | G3: H | H3: Atlanta Falcons | I3: 32 | J3: 6 | K3: 434 | L3: 0 | M3: 260 | N3: 0 | O3: =I3-J3 -> 26
A4: 1 | B4: Sun | C4: 44451 | D4: 1:00PM | E4: V | F4: Pittsburgh Steelers | G4: H | H4: Buffalo Bills | I4: 23 | J4: 16 | K4: 252 | L4: 0 | M4: 371 | N4: 1 | O4: =I4-J4 -> 7
A5: 1 | B5: Sun | C5: 44451 | D5: 1:00PM | E5: H | F5: Carolina Panthers | G5: V | H5: New York Jets | I5: 19 | J5: 14 | K5: 381 | L5: 1 | M5: 252 | N5: 1 | O5: =I5-J5 -> 5
A6: 1 | B6: Sun | C6: 44451 | D6: 1:00PM | E6: H | F6: Cincinnati Bengals | G6: V | H6: Minnesota Vikings | I6: 27 | J6: 24 | K6: 366 | L6: 0 | M6: 403 | N6: 1 | O6: =I6-J6 -> 3
A7: 1 | B7: Sun | C7: 44451 | D7: 1:00PM | E7: V | F7: Seattle Seahawks | G7: H | H7: Indianapolis Colts | I7: 28 | J7: 16 | K7: 381 | L7: 1 | M7: 336 | N7: 1 | O7: =I7-J7 -> 12
A8: 1 | B8: Sun | C8: 44451 | D8: 1:00PM | E8: V | F8: Arizona Cardinals | G8: H | H8: Tennessee Titans | I8: 38 | J8: 13 | K8: 416 | L8: 1 | M8: 248 | N8: 3 | O8: =I8-J8 -> 25
A9: 1 | B9: Sun | C9: 44451 | D9: 1:00PM | E9: V | F9: San Francisco 49ers | G9: H | H9: Detroit Lions | I9: 41 | J9: 33 | K9: 442 | L9: 2 | M9: 430 | N9: 1 | O9: =I9-J9 -> 8
A10: 1 | B10: Sun | C10: 44451 | D10: 1:00PM | E10: H | F10: Houston Texans | G10: V | H10: Jacksonville Jaguars | I10: 37 | J10: 21 | K10: 449 | L10: 0 | M10: 395 | N10: 3 | O10: =I10-J10 -> 16
A11: 1 | B11: Sun | C11: 44451 | D11: 1:00PM | E11: V | F11: Los Angeles Chargers | G11: H | H11: Washington Football Team | I11: 20 | J11: 16 | K11: 424 | L11: 2 | M11: 259 | N11: 1 | O11: =I11-J11 -> 4
A12: 1 | B12: Sun | C12: 44451 | D12: 4:25PM | E12: H | F12: Kansas City Chiefs | G12: V | H12: Cleveland Browns | I12: 33 | J12: 29 | K12: 397 | L12: 0 | M12: 457 | N12: 2 | O12: =I12-J12 -> 4
A13: 1 | B13: Sun | C13: 44451 | D13: 4:25PM | E13: V | F13: Denver Broncos | G13: H | H13: New York Giants | I13: 27 | J13: 13 | K13: 420 | L13: 1 | M13: 314 | N13: 1 | O13: =I13-J13 -> 14
... A140: 10 | B140: Sun | C140: 44514 | D140: 1:00PM | E140: V | F140: Buffalo Bills | G140: H | H140: New York Jets | I140: 45 | J140: 17 | K140: 489 | L140: 2 | M140: 366 | N140: 5 | O140: =I140-J140 -> 28
A141: 10 | B141: Sun | C141: 44514 | D141: 1:00PM | E141: H | F141: Pittsburgh Steelers | G141: V | H141: Detroit Lions | I141: 16 | J141: 16 | K141: 387 | L141: 3 | M141: 306 | N141: 0
A142: 10 | B142: Sun | C142: 44514 | D142: 1:00PM | E142: H | F142: Tennessee Titans | G142: V | H142: New Orleans Saints | I142: 23 | J142: 21 | K142: 264 | L142: 0 | M142: 373 | N142: 1 | O142: =I142-J142 -> 2
A143: 10 | B143: Sun | C143: 44514 | D143: 1:00PM | E143: H | F143: Washington Football Team | G143: V | H143: Tampa Bay Buccaneers | I143: 29 | J143: 19 | K143: 320 | L143: 1 | M143: 273 | N143: 2 | O143: =I143-J143 -> 10
A144: 10 | B144: Sun | C144: 44514 | D144: 1:00PM | E144: H | F144: New England Patriots | G144: V | H144: Cleveland Browns | I144: 45 | J144: 7 | K144: 452 | L144: 0 | M144: 217 | N144: 1 | O144: =I144-J144 -> 38
A145: 10 | B145: Sun | C145: 44514 | D145: 1:00PM | E145: H | F145: Indianapolis Colts | G145: V | H145: Jacksonville Jaguars | I145: 23 | J145: 17 | K145: 295 | L145: 0 | M145: 331 | N145: 1 | O145: =I145-J145 -> 6
A146: 10 | B146: Sun | C146: 44514 | D146: 4:05PM | E146: V | F146: Minnesota Vikings | G146: H | H146: Los Angeles Chargers | I146: 27 | J146: 20 | K146: 381 | L146: 1 | M146: 253 | N146: 1 | O146: =I146-J146 -> 7
A147: 10 | B147: Sun | C147: 44514 | D147: 4:05PM | E147: V | F147: Carolina Panthers | G147: H | H147: Arizona Cardinals | I147: 34 | J147: 10 | K147: 341 | L147: 2 | M147: 169 | N147: 2 | O147: =I147-J147 -> 24
A148: 10 | B148: Sun | C148: 44514 | D148: 4:25PM | E148: V | F148: Philadelphia Eagles | G148: H | H148: Denver Broncos | I148: 30 | J148: 13 | K148: 386 | L148: 1 | M148: 308 | N148: 1 | O148: =I148-J148 -> 17
A149: 10 | B149: Sun | C149: 44514 | D149: 4:25PM | E149: H | F149: Green Bay Packers | G149: V | H149: Seattle Seahawks | I149: 17 | J149: 0 | K149: 393 | L149: 1 | M149: 208 | N149: 2 | O149: =I149-J149 -> 17
A150: 10 | B150: Sun | C150: 44514 | D150: 8:20PM | E150: V | F150: Kansas City Chiefs | G150: H | H150: Las Vegas Raiders | I150: 41 | J150: 14 | K150: 516 | L150: 1 | M150: 299 | N150: 2 | O150: =I150-J150 -> 27
A151: 10 | B151: Mon | C151: 44515 | D151: 8:15PM | E151: H | F151: San Francisco 49ers | G151: V | H151: Los Angeles Rams | I151: 31 | J151: 10 | K151: 335 | L151: 0 | M151: 278 | N151: 2 | O151: =I151-J151 -> 21
A152: 11 | B152: Thu | C152: 44518 | D152: 8:20PM | E152: V | F152: New England Patriots | G152: H | H152: Atlanta Falcons | I152: 25 | J152: 0 | K152: 308 | L152: 1 | M152: 165 | N152: 4 | O152: =I152-J152 -> 25
A153: 11 | B153: Sun | C153: 44521 | D153: 1:00PM | E153: V | F153: Indianapolis Colts | G153: H | H153: Buffalo Bills | I153: 41 | J153: 15 | K153: 370 | L153: 0 | M153: 311 | N153: 4 | O153: =I153-J153 -> 26
... A273: 18 | B273: Sun | C273: 44570 | D273: 8:25PM | E273: H | F273: Las Vegas Raiders | G273: V | H273: Los Angeles Chargers | I273: 35 | J273: 32 | K273: 346 | L273: 0 | M273: 440 | N273: 2 | O273: =I273-J273 -> 3
A274: WildCard | B274: Sat | C274: 44576 | D274: 4:30PM | E274: H | F274: Cincinnati Bengals | G274: V | H274: Las Vegas Raiders | I274: 26 | J274: 19 | K274: 308 | L274: 0 | M274: 385 | N274: 2 | O274: =I274-J274 -> 7
A275: WildCard | B275: Sat | C275: 44576 | D275: 8:15PM | E275: H | F275: Buffalo Bills | G275: V | H275: New England Patriots | I275: 47 | J275: 17 | K275: 482 | L275: 0 | M275: 305 | N275: 2 | O275: =I275-J275 -> 30
A276: WildCard | B276: Sun | C276: 44577 | D276: 1:00PM | E276: H | F276: Tampa Bay Buccaneers | G276: V | H276: Philadelphia Eagles | I276: 31 | J276: 15 | K276: 349 | L276: 0 | M276: 339 | N276: 3 | O276: =I276-J276 -> 16
A277: WildCard | B277: Sun | C277: 44577 | D277: 4:40PM | E277: V | F277: San Francisco 49ers | G277: H | H277: Dallas Cowboys | I277: 23 | J277: 17 | K277: 341 | L277: 1 | M277: 307 | N277: 1 | O277: =I277-J277 -> 6
A278: WildCard | B278: Sun | C278: 44577 | D278: 8:15PM | E278: H | F278: Kansas City Chiefs | G278: V | H278: Pittsburgh Steelers | I278: 42 | J278: 21 | K278: 478 | L278: 2 | M278: 257 | N278: 1 | O278: =I278-J278 -> 21
A279: WildCard | B279: Mon | C279: 44578 | D279: 8:15PM | E279: H | F279: Los Angeles Rams | G279: V | H279: Arizona Cardinals | I279: 34 | J279: 11 | K279: 375 | L279: 0 | M279: 183 | N279: 2 | O279: =I279-J279 -> 23
A280: Division | B280: Sat | C280: 44583 | D280: 4:30PM | E280: V | F280: Cincinnati Bengals | G280: H | H280: Tennessee Titans | I280: 19 | J280: 16 | K280: 345 | L280: 1 | M280: 353 | N280: 3 | O280: =I280-J280 -> 3
A281: Division | B281: Sat | C281: 44583 | D281: 8:15PM | E281: V | F281: San Francisco 49ers | G281: H | H281: Green Bay Packers | I281: 13 | J281: 10 | K281: 212 | L281: 1 | M281: 263 | N281: 1 | O281: =I281-J281 -> 3
A282: Division | B282: Sun | C282: 44584 | D282: 3:00PM | E282: V | F282: Los Angeles Rams | G282: H | H282: Tampa Bay Buccaneers | I282: 30 | J282: 27 | K282: 428 | L282: 4 | M282: 359 | N282: 2 | O282: =I282-J282 -> 3
A283: Division | B283: Sun | C283: 44584 | D283: 6:30PM | E283: H | F283: Kansas City Chiefs | G283: V | H283: Buffalo Bills | I283: 42 | J283: 36 | K283: 552 | L283: 0 | M283: 422 | N283: 0 | O283: =I283-J283 -> 6
A284: ConfChamp | B284: Sun | C284: 44591 | D284: 3:00PM | E284: V | F284: Cincinnati Bengals | G284: H | H284: Kansas City Chiefs | I284: 27 | J284: 24 | K284: 359 | L284: 1 | M284: 375 | N284: 2 | O284: =I284-J284 -> 3
A285: ConfChamp | B285: Sun | C285: 44591 | D285: 6:30PM | E285: H | F285: Los Angeles Rams | G285: V | H285: San Francisco 49ers | I285: 20 | J285: 17 | K285: 396 | L285: 1 | M285: 282 | N285: 1 | O285: =I285-J285 -> 3
...

Sheet Sheet1

Sheet Teams
A1: Teams | B1: First Places | C1: Last Places | D1: NFC/AFC | E1: Division | F1: Total Wins | G1: Total Loses | H1: Total Wins @ Home | I1: Total Loses @ Home | J1: Total Wins Away | K1: Total Loses Away | L1: Total Points Scored | M1: Average Points | N1: Total Points Allowed | O1: Average Points Allowed | P1: Points Differential | Q1: Average Points Differential | R1: Total Yards | S1: Total Yards Allowed | T1: Average Yards | U1: Average Yards Allowed | V1: Total Yards Differential | W1: Avg Yard Differential | X1: If Win, Points Scored | Y1: If Win Average | Z1: If Win, Opponent Scored | AA1: If Win Opponent Average | AB1: Win Total Differential | AC1: Win Average Pts Differential | AD1: If Loss, Points Scored | AE1: If Loss, Points Average | AF1: If Loss, Opponent Scored | AG1: If Loss, Opponents Average | AH1: If Loss, Total Pts Differential | AI1: If Loss, Avg Pts Differential | AJ1: Closet Win | AK1: Closest Loss | AL1: Biggest Win | AM1: Biggest Loss | AN1: Most Points | AO1: Least Points | AP1: Most Yards | AQ1: Least Yards | AR1: If Win, Average Yards | AS1: If Win, Average Opponents Yards | AT1: Win, Avg Yards Differential | AU1: If Lose, Average Yards | AV1: If Lose, Average Opponents Yards | AW1: Lose, Yards Differential | AX1: Average Points @ Home | AY1: Average Yards @ Homes | AZ1: Average Points Away | BA1: Average Yards Away
A2: Tampa Bay Buccaneers | B2: =COUNTIF($35:$35,A2) -> 3 | C2: =COUNTIF($36:$36,A2) -> 1 | D2: NFC | E2: South | F2: =COUNTIF(Stats!F:F,A2) -> 14 | G2: =COUNTIF(Stats!H:H,A2) -> 5 | H2: =COUNTIFS(Stats!F:F,A2,Stats!E:E,"H") -> 8 | I2: =COUNTIFS(Stats!H:H,A2,Stats!G:G,"H") -> 2 | J2: =F2-H2 -> 6 | K2: =G2-I2 -> 3 | L2: =SUMIFS(Stats!I:I,Stats!F:F,A2)+SUMIFS(Stats!J:J,Stats!H:H,A2) -> 569 | M2: =L2/(F2+G2) -> 29.947368 | N2: =SUMIFS(Stats!I:I,Stats!H:H,A2)+SUMIFS(Stats!J:J,Stats!F:F,A2) -> 398 | O2: =N2/SUM(F2,G2) -> 20.947368 | P2: =L2-N2 -> 171 | Q2: =P2/(F2+G2) -> 9 | R2: =SUMIFS(Stats!K:K,Stats!F:F,A2)+SUMIFS(Stats!M:M,Stats!H:H,A2) -> 7609 | S2: =SUMIFS(Stats!K:K,Stats!H:H,A2)+SUMIFS(Stats!M:M,Stats!F:F,A2) -> 6402 | T2: =R2/(F2+G2) -> 400.47368 | U2: =S2/(F2+G2) -> 336.94737 | V2: =R2-S2 -> 1207 | W2: =T2-U2 -> 63.526316 | X2: =SUMIFS(Stats!I:I,Stats!F:F,A2) -> 472 | Y2: =X2/F2 -> 33.714286 | Z2: =SUMIFS(Stats!J:J,Stats!F:F,A2) -> 260 | AA2: =Z2/F2 -> 18.571429 | AB2: =X2-Z2 -> 212 | AC2: =Y2-AA2 -> 15.142857 | AD2: =SUMIFS(Stats!J:J,Stats!H:H,A2) -> 97 | AE2: =AD2/G2 -> 19.4 | AF2: =SUMIFS(Stats!I:I,Stats!H:H,A2) -> 138 | AG2: =AF2/G2 -> 27.6 | AH2: =AD2-AF2 -> -41 | AI2: =AE2-AG2 -> -8.2 | AJ2: =_xlfn.MINIFS(Stats!O:O,Stats!F:F,A2) -> 2 | AK2: =-_xlfn.MINIFS(Stats!O:O,Stats!H:H,A2) -> -3 | AL2: =_xlfn.MAXIFS(Stats!O:O,Stats!F:F,A2) -> 35 | AM2: =-_xlfn.MAXIFS(Stats!O:O,Stats!H:H,A2) -> -10 | AN2: =_xlfn.MAXIFS(Stats!I:I,Stats!F:F,A2) -> 48 | AO2: =IF(_xlfn.MINIFS(Stats!I:I,Stats!F:F,A2)<_xlfn.MINIFS(Stats!J:J,Stats!H:H,A2),_xlfn.MINIFS(Stats!I:I,Stats!F:F,A2),_xlfn.MINIFS(Stats!J:J,Stats!H:H,A2)) -> 0 | AP2: =IF(_xlfn.MAXIFS(Stats!K:K,Stats!F:F,A2)>_xlfn.MAXIFS(Stats!M:M,Stats!H:H,A2),_xlfn.MAXIFS(Stats!K:K,Stats!F:F,A2),_xlfn.MAXIFS(Stats!M:M,Stats!H:H,A2)) -> 558 | AQ2: =IF(_xlfn.MINIFS(Stats!M:M,Stats!H:H,A2)<_xlfn.MINIFS(Stats!K:K,Stats!F:F,A2),_xlfn.MINIFS(Stats!M:M,Stats!H:H,A2),_xlfn.MINIFS(Stats!K:K,Stats!F:F,A2)) -> 273 | AR2: =SUMIFS(Stats!K:K,Stats!F:F,A2)/F2 -> 414.85714 | AS2: =SUMIFS(Stats!M:M,Stats!F:F,A2)/F2 -> 333.85714 | AT2: =AR2-AS2 -> 81 | AU2: =SUMIFS(Stats!M:M,Stats!H:H,A2)/G2 -> 360.2 | AV2: =SUMIFS(Stats!K:K,Stats!H:H,A2)/G2 -> 345.6 | AW2: =AU2-AV2 -> 14.6 | AX2: =(SUMIFS(Stats!I:I,Stats!E:E,"H",Stats!F:F,A2)+SUMIFS(Stats!J:J,Stats!H:H,A2,Stats!G:G,"H"))/(H2+I2) -> 32.4 | AY2: =(SUMIFS(Stats!K:K,Stats!F:F,A2,Stats!E:E,"H")+SUMIFS(Stats!M:M,Stats!G:G,"H",Stats!H:H,A2))/(H2+I2) -> 404.7 | AZ2: =(SUMIFS(Stats!I:I,Stats!E:E,"V",Stats!F:F,A2)+SUMIFS(Stats!J:J,Stats!H:H,A2,Stats!G:G,"V"))/(J2+K2) -> 27.222222 | BA2: =(SUMIFS(Stats!K:K,Stats!F:F,A2,Stats!E:E,"V")+SUMIFS(Stats!M:M,Stats!G:G,"V",Stats!H:H,A2))/(J2+K2) -> 395.77778
A3: Philadelphia Eagles | B3: =COUNTIF($35:$35,A3) -> 0 | C3: =COUNTIF($36:$36,A3) -> 0 | D3: NFC | E3: East | F3: =COUNTIF(Stats!F:F,A3) -> 9 | G3: =COUNTIF(Stats!H:H,A3) -> 9 | H3: =COUNTIFS(Stats!F:F,A3,Stats!E:E,"H") -> 3 | I3: =COUNTIFS(Stats!H:H,A3,Stats!G:G,"H") -> 5 | J3: =F3-H3 -> 6 | K3: =G3-I3 -> 4 | L3: =SUMIFS(Stats!I:I,Stats!F:F,A3)+SUMIFS(Stats!J:J,Stats!H:H,A3) -> 459 | M3: =L3/(F3+G3) -> 25.5 | N3: =SUMIFS(Stats!I:I,Stats!H:H,A3)+SUMIFS(Stats!J:J,Stats!F:F,A3) -> 416 | O3: =N3/SUM(F3,G3) -> 23.111111 | P3: =L3-N3 -> 43 | Q3: =P3/(F3+G3) -> 2.3888889 | R3: =SUMIFS(Stats!K:K,Stats!F:F,A3)+SUMIFS(Stats!M:M,Stats!H:H,A3) -> 6458 | S3: =SUMIFS(Stats!K:K,Stats!H:H,A3)+SUMIFS(Stats!M:M,Stats!F:F,A3) -> 5939 | T3: =R3/(F3+G3) -> 358.77778 | U3: =S3/(F3+G3) -> 329.94444 | V3: =R3-S3 -> 519 | W3: =T3-U3 -> 28.833333 | X3: =SUMIFS(Stats!I:I,Stats!F:F,A3) -> 281 | Y3: =X3/F3 -> 31.222222 | Z3: =SUMIFS(Stats!J:J,Stats!F:F,A3) -> 133 | AA3: =Z3/F3 -> 14.777778 | AB3: =X3-Z3 -> 148 | AC3: =Y3-AA3 -> 16.444444 | AD3: =SUMIFS(Stats!J:J,Stats!H:H,A3) -> 178 | AE3: =AD3/G3 -> 19.777778 | AF3: =SUMIFS(Stats!I:I,Stats!H:H,A3) -> 283 | AG3: =AF3/G3 -> 31.444444 | AH3: =AD3-AF3 -> -105 | AI3: =AE3-AG3 -> -11.666667 | AJ3: =_xlfn.MINIFS(Stats!O:O,Stats!F:F,A3) -> 3 | AK3: =-_xlfn.MINIFS(Stats!O:O,Stats!H:H,A3) -> -3 | AL3: =_xlfn.MAXIFS(Stats!O:O,Stats!F:F,A3) -> 38 | AM3: =-_xlfn.MAXIFS(Stats!O:O,Stats!H:H,A3) -> -25 | AN3: =_xlfn.MAXIFS(Stats!I:I,Stats!F:F,A3) -> 44 | AO3: =IF(_xlfn.MINIFS(Stats!I:I,Stats!F:F,A3)<_xlfn.MINIFS(Stats!J:J,Stats!H:H,A3),_xlfn.MINIFS(Stats!I:I,Stats!F:F,A3),_xlfn.MINIFS(Stats!J:J,Stats!H:H,A3)) -> 7 | AP3: =IF(_xlfn.MAXIFS(Stats!K:K,Stats!F:F,A3)>_xlfn.MAXIFS(Stats!M:M,Stats!H:H,A3),_xlfn.MAXIFS(Stats!K:K,Stats!F:F,A3),_xlfn.MAXIFS(Stats!M:M,Stats!H:H,A3)) -> 519 | AQ3: =IF(_xlfn.MINIFS(Stats!M:M,Stats!H:H,A3)<_xlfn.MINIFS(Stats!K:K,Stats!F:F,A3),_xlfn.MINIFS(Stats!M:M,Stats!H:H,A3),_xlfn.MINIFS(Stats!K:K,Stats!F:F,A3)) -> 213 | AR3: =SUMIFS(Stats!K:K,Stats!F:F,A3)/F3 -> 379.33333 | AS3: =SUMIFS(Stats!M:M,Stats!F:F,A3)/F3 -> 267.55556 | AT3: =AR3-AS3 -> 111.77778 | AU3: =SUMIFS(Stats!M:M,Stats!H:H,A3)/G3 -> 338.22222 | AV3: =SUMIFS(Stats!K:K,Stats!H:H,A3)/G3 -> 392.33333 | AW3: =AU3-AV3 -> -54.111111 | AX3: =(SUMIFS(Stats!I:I,Stats!E:E,"H",Stats!F:F,A3)+SUMIFS(Stats!J:J,Stats!H:H,A3,Stats!G:G,"H"))/(H3+I3) -> 26.75 | AY3: =(SUMIFS(Stats!K:K,Stats!F:F,A3,Stats!E:E,"H")+SUMIFS(Stats!M:M,Stats!G:G,"H",Stats!H:H,A3))/(H3+I3) -> 358.875 | AZ3: =(SUMIFS(Stats!I:I,Stats!E:E,"V",Stats!F:F,A3)+SUMIFS(Stats!J:J,Stats!H:H,A3,Stats!G:G,"V"))/(J3+K3) -> 24.5 | BA3: =(SUMIFS(Stats!K:K,Stats!F:F,A3,Stats!E:E,"V")+SUMIFS(Stats!M:M,Stats!G:G,"V",Stats!H:H,A3))/(J3+K3) -> 358.7
A4: Pittsburgh Steelers | B4: =COUNTIF($35:$35,A4) -> 0 | C4: =COUNTIF($36:$36,A4) -> 2 | D4: AFC | E4: North | F4: =COUNTIF(Stats!F:F,A4) -> 10 | G4: =COUNTIF(Stats!H:H,A4) -> 8 | H4: =COUNTIFS(Stats!F:F,A4,Stats!E:E,"H") -> 7 | I4: =COUNTIFS(Stats!H:H,A4,Stats!G:G,"H") -> 2 | J4: =F4-H4 -> 3 | K4: =G4-I4 -> 6 | L4: =SUMIFS(Stats!I:I,Stats!F:F,A4)+SUMIFS(Stats!J:J,Stats!H:H,A4) -> 364 | M4: =L4/(F4+G4) -> 20.222222 | N4: =SUMIFS(Stats!I:I,Stats!H:H,A4)+SUMIFS(Stats!J:J,Stats!F:F,A4) -> 440 | O4: =N4/SUM(F4,G4) -> 24.444444 | P4: =L4-N4 -> -76 | Q4: =P4/(F4+G4) -> -4.2222222 | R4: =SUMIFS(Stats!K:K,Stats!F:F,A4)+SUMIFS(Stats!M:M,Stats!H:H,A4) -> 5618 | S4: =SUMIFS(Stats!K:K,Stats!H:H,A4)+SUMIFS(Stats!M:M,Stats!F:F,A4) -> 6617 | T4: =R4/(F4+G4) -> 312.11111 | U4: =S4/(F4+G4) -> 367.61111 | V4: =R4-S4 -> -999 | W4: =T4-U4 -> -55.5 | X4: =SUMIFS(Stats!I:I,Stats!F:F,A4) -> 214 | Y4: =X4/F4 -> 21.4 | Z4: =SUMIFS(Stats!J:J,Stats!F:F,A4) -> 167 | AA4: =Z4/F4 -> 16.7 | AB4: =X4-Z4 -> 47 | AC4: =Y4-AA4 -> 4.7 | AD4: =SUMIFS(Stats!J:J,Stats!H:H,A4) -> 150 | AE4: =AD4/G4 -> 18.75 | AF4: =SUMIFS(Stats!I:I,Stats!H:H,A4) -> 273 | AG4: =AF4/G4 -> 34.125 | AH4: =AD4-AF4 -> -123 | AI4: =AE4-AG4 -> -15.375 | AJ4: =_xlfn.MINIFS(Stats!O:O,Stats!F:F,A4) -> 1 | AK4: =-_xlfn.MINIFS(Stats!O:O,Stats!H:H,A4) -> -4 | AL4: =_xlfn.MAXIFS(Stats!O:O,Stats!F:F,A4) -> 12 | AM4: =-_xlfn.MAXIFS(Stats!O:O,Stats!H:H,A4) -> -31 | AN4: =_xlfn.MAXIFS(Stats!I:I,Stats!F:F,A4) -> 29 | AO4: =IF(_xlfn.MINIFS(Stats!I:I,Stats!F:F,A4)<_xlfn.MINIFS(Stats!J:J,Stats!H:H,A4),_xlfn.MINIFS(Stats!I:I,Stats!F:F,A4),_xlfn.MINIFS(Stats!J:J,Stats!H:H,A4)) -> 10 | AP4: =IF(_xlfn.MAXIFS(Stats!K:K,Stats!F:F,A4)>_xlfn.MAXIFS(Stats!M:M,Stats!H:H,A4),_xlfn.MAXIFS(Stats!K:K,Stats!F:F,A4),_xlfn.MAXIFS(Stats!M:M,Stats!H:H,A4)) -> 391 | AQ4: =IF(_xlfn.MINIFS(Stats!M:M,Stats!H:H,A4)<_xlfn.MINIFS(Stats!K:K,Stats!F:F,A4),_xlfn.MINIFS(Stats!M:M,Stats!H:H,A4),_xlfn.MINIFS(Stats!K:K,Stats!F:F,A4)) -> 168 | AR4: =SUMIFS(Stats!K:K,Stats!F:F,A4)/F4 -> 312.7 | AS4: =SUMIFS(Stats!M:M,Stats!F:F,A4)/F4 -> 333.7 | AT4: =AR4-AS4 -> -21 | AU4: =SUMIFS(Stats!M:M,Stats!H:H,A4)/G4 -> 311.375 | AV4: =SUMIFS(Stats!K:K,Stats!H:H,A4)/G4 -> 410 | AW4: =AU4-AV4 -> -98.625 | AX4: =(SUMIFS(Stats!I:I,Stats!E:E,"H",Stats!F:F,A4)+SUMIFS(Stats!J:J,Stats!H:H,A4,Stats!G:G,"H"))/(H4+I4) -> 20.777778 | AY4: =(SUMIFS(Stats!K:K,Stats!F:F,A4,Stats!E:E,"H")+SUMIFS(Stats!M:M,Stats!G:G,"H",Stats!H:H,A4))/(H4+I4) -> 318.22222 | AZ4: =(SUMIFS(Stats!I:I,Stats!E:E,"V",Stats!F:F,A4)+SUMIFS(Stats!J:J,Stats!H:H,A4,Stats!G:G,"V"))/(J4+K4) -> 19.666667 | BA4: =(SUMIFS(Stats!K:K,Stats!F:F,A4,Stats!E:E,"V")+SUMIFS(Stats!M:M,Stats!G:G,"V",Stats!H:H,A4))/(J4+K4) -> 306
A5: Carolina Panthers | B5: =COUNTIF($35:$35,A5) -> 4 | C5: =COUNTIF($36:$36,A5) -> 1 | D5: NFC | E5: South | F5: =COUNTIF(Stats!F:F,A5) -> 5 | G5: =COUNTIF(Stats!H:H,A5) -> 12 | H5: =COUNTIFS(Stats!F:F,A5,Stats!E:E,"H") -> 2 | I5: =COUNTIFS(Stats!H:H,A5,Stats!G:G,"H") -> 6 | J5: =F5-H5 -> 3 | K5: =G5-I5 -> 6 | L5: =SUMIFS(Stats!I:I,Stats!F:F,A5)+SUMIFS(Stats!J:J,Stats!H:H,A5) -> 304 | M5: =L5/(F5+G5) -> 17.882353 | N5: =SUMIFS(Stats!I:I,Stats!H:H,A5)+SUMIFS(Stats!J:J,Stats!F:F,A5) -> 404 | O5: =N5/SUM(F5,G5) -> 23.764706 | P5: =L5-N5 -> -100 | Q5: =P5/(F5+G5) -> -5.8823529 | R5: =SUMIFS(Stats!K:K,Stats!F:F,A5)+SUMIFS(Stats!M:M,Stats!H:H,A5) -> 5081 | S5: =SUMIFS(Stats!K:K,Stats!H:H,A5)+SUMIFS(Stats!M:M,Stats!F:F,A5) -> 5201 | T5: =R5/(F5+G5) -> 298.88235 | U5: =S5/(F5+G5) -> 305.94118 | V5: =R5-S5 -> -120 | W5: =T5-U5 -> -7.0588235 | X5: =SUMIFS(Stats!I:I,Stats!F:F,A5) -> 122 | Y5: =X5/F5 -> 24.4 | Z5: =SUMIFS(Stats!J:J,Stats!F:F,A5) -> 53 | AA5: =Z5/F5 -> 10.6 | AB5: =X5-Z5 -> 69 | AC5: =Y5-AA5 -> 13.8 | AD5: =SUMIFS(Stats!J:J,Stats!H:H,A5) -> 182 | AE5: =AD5/G5 -> 15.166667 | AF5: =SUMIFS(Stats!I:I,Stats!H:H,A5) -> 351 | AG5: =AF5/G5 -> 29.25 | AH5: =AD5-AF5 -> -169 | AI5: =AE5-AG5 -> -14.083333 | AJ5: =_xlfn.MINIFS(Stats!O:O,Stats!F:F,A5) -> 5 | AK5: =-_xlfn.MINIFS(Stats!O:O,Stats!H:H,A5) -> -3 | AL5: =_xlfn.MAXIFS(Stats!O:O,Stats!F:F,A5) -> 24 | AM5: =-_xlfn.MAXIFS(Stats!O:O,Stats!H:H,A5) -> -26 | AN5: =_xlfn.MAXIFS(Stats!I:I,Stats!F:F,A5) -> 34 | AO5: =IF(_xlfn.MINIFS(Stats!I:I,Stats!F:F,A5)<_xlfn.MINIFS(Stats!J:J,Stats!H:H,A5),_xlfn.MINIFS(Stats!I:I,Stats!F:F,A5),_xlfn.MINIFS(Stats!J:J,Stats!H:H,A5)) -> 3 | AP5: =IF(_xlfn.MAXIFS(Stats!K:K,Stats!F:F,A5)>_xlfn.MAXIFS(Stats!M:M,Stats!H:H,A5),_xlfn.MAXIFS(Stats!K:K,Stats!F:F,A5),_xlfn.MAXIFS(Stats!M:M,Stats!H:H,A5)) -> 407 | AQ5: =IF(_xlfn.MINIFS(Stats!M:M,Stats!H:H,A5)<_xlfn.MINIFS(Stats!K:K,Stats!F:F,A5),_xlfn.MINIFS(Stats!M:M,Stats!H:H,A5),_xlfn.MINIFS(Stats!K:K,Stats!F:F,A5)) -> 173 | AR5: =SUMIFS(Stats!K:K,Stats!F:F,A5)/F5 -> 368.8 | AS5: =SUMIFS(Stats!M:M,Stats!F:F,A5)/F5 -> 191 | AT5: =AR5-AS5 -> 177.8 | AU5: =SUMIFS(Stats!M:M,Stats!H:H,A5)/G5 -> 269.75 | AV5: =SUMIFS(Stats!K:K,Stats!H:H,A5)/G5 -> 353.83333 | AW5: =AU5-AV5 -> -84.083333 | AX5: =(SUMIFS(Stats!I:I,Stats!E:E,"H",Stats!F:F,A5)+SUMIFS(Stats!J:J,Stats!H:H,A5,Stats!G:G,"H"))/(H5+I5) -> 18.125 | AY5: =(SUMIFS(Stats!K:K,Stats!F:F,A5,Stats!E:E,"H")+SUMIFS(Stats!M:M,Stats!G:G,"H",Stats!H:H,A5))/(H5+I5) -> 310.125 | AZ5: =(SUMIFS(Stats!I:I,Stats!E:E,"V",Stats!F:F,A5)+SUMIFS(Stats!J:J,Stats!H:H,A5,Stats!G:G,"V"))/(J5+K5) -> 17.666667 | BA5: =(SUMIFS(Stats!K:K,Stats!F:F,A5,Stats!E:E,"V")+SUMIFS(Stats!M:M,Stats!G:G,"V",Stats!H:H,A5))/(J5+K5) -> 288.88889
A6: Cincinnati Bengals | B6: =COUNTIF($35:$35,A6) -> 2 | C6: =COUNTIF($36:$36,A6) -> 1 | D6: AFC | E6: North | F6: =COUNTIF(Stats!F:F,A6) -> 13 | G6: =COUNTIF(Stats!H:H,A6) -> 8 | H6: =COUNTIFS(Stats!F:F,A6,Stats!E:E,"H") -> 6 | I6: =COUNTIFS(Stats!H:H,A6,Stats!G:G,"H") -> 4 | J6: =F6-H6 -> 7 | K6: =G6-I6 -> 4 | L6: =SUMIFS(Stats!I:I,Stats!F:F,A6)+SUMIFS(Stats!J:J,Stats!H:H,A6) -> 552 | M6: =L6/(F6+G6) -> 26.285714 | N6: =SUMIFS(Stats!I:I,Stats!H:H,A6)+SUMIFS(Stats!J:J,Stats!F:F,A6) -> 458 | O6: =N6/SUM(F6,G6) -> 21.809524 | P6: =L6-N6 -> 94 | Q6: =P6/(F6+G6) -> 4.4761905 | R6: =SUMIFS(Stats!K:K,Stats!F:F,A6)+SUMIFS(Stats!M:M,Stats!H:H,A6) -> 7462 | S6: =SUMIFS(Stats!K:K,Stats!H:H,A6)+SUMIFS(Stats!M:M,Stats!F:F,A6) -> 7390 | T6: =R6/(F6+G6) -> 355.33333 | U6: =S6/(F6+G6) -> 351.90476 | V6: =R6-S6 -> 72 | W6: =T6-U6 -> 3.4285714 | X6: =SUMIFS(Stats!I:I,Stats!F:F,A6) -> 385 | Y6: =X6/F6 -> 29.615385 | Z6: =SUMIFS(Stats!J:J,Stats!F:F,A6) -> 227 | AA6: =Z6/F6 -> 17.461538 | AB6: =X6-Z6 -> 158 | AC6: =Y6-AA6 -> 12.153846 | AD6: =SUMIFS(Stats!J:J,Stats!H:H,A6) -> 167 | AE6: =AD6/G6 -> 20.875 | AF6: =SUMIFS(Stats!I:I,Stats!H:H,A6) -> 231 | AG6: =AF6/G6 -> 28.875 | AH6: =AD6-AF6 -> -64 | AI6: =AE6-AG6 -> -8 | AJ6: =_xlfn.MINIFS(Stats!O:O,Stats!F:F,A6) -> 3 | AK6: =-_xlfn.MINIFS(Stats!O:O,Stats!H:H,A6) -> -3 | AL6: =_xlfn.MAXIFS(Stats!O:O,Stats!F:F,A6) -> 31 | AM6: =-_xlfn.MAXIFS(Stats!O:O,Stats!H:H,A6) -> -25 | AN6: =_xlfn.MAXIFS(Stats!I:I,Stats!F:F,A6) -> 41 | AO6: =IF(_xlfn.MINIFS(Stats!I:I,Stats!F:F,A6)<_xlfn.MINIFS(Stats!J:J,Stats!H:H,A6),_xlfn.MINIFS(Stats!I:I,Stats!F:F,A6),_xlfn.MINIFS(Stats!J:J,Stats!H:H,A6)) -> 15 | AP6: =IF(_xlfn.MAXIFS(Stats!K:K,Stats!F:F,A6)>_xlfn.MAXIFS(Stats!M:M,Stats!H:H,A6),_xlfn.MAXIFS(Stats!K:K,Stats!F:F,A6),_xlfn.MAXIFS(Stats!M:M,Stats!H:H,A6)) -> 575 | AQ6: =IF(_xlfn.MINIFS(Stats!M:M,Stats!H:H,A6)<_xlfn.MINIFS(Stats!K:K,Stats!F:F,A6),_xlfn.MINIFS(Stats!M:M,Stats!H:H,A6),_xlfn.MINIFS(Stats!K:K,Stats!F:F,A6)) -> 182 | AR6: =SUMIFS(Stats!K:K,Stats!F:F,A6)/F6 -> 380.07692 | AS6: =SUMIFS(Stats!M:M,Stats!F:F,A6)/F6 -> 341.46154 | AT6: =AR6-AS6 -> 38.615385 | AU6: =SUMIFS(Stats!M:M,Stats!H:H,A6)/G6 -> 315.125 | AV6: =SUMIFS(Stats!K:K,Stats!H:H,A6)/G6 -> 368.875 | AW6: =AU6-AV6 -> -53.75 | AX6: =(SUMIFS(Stats!I:I,Stats!E:E,"H",Stats!F:F,A6)+SUMIFS(Stats!J:J,Stats!H:H,A6,Stats!G:G,"H"))/(H6+I6) -> 27.6 | AY6: =(SUMIFS(Stats!K:K,Stats!F:F,A6,Stats!E:E,"H")+SUMIFS(Stats!M:M,Stats!G:G,"H",Stats!H:H,A6))/(H6+I6) -> 398.2 | AZ6: =(SUMIFS(Stats!I:I,Stats!E:E,"V",Stats!F:F,A6)+SUMIFS(Stats!J:J,Stats!H:H,A6,Stats!G:G,"V"))/(J6+K6) -> 25.090909 | BA6: =(SUMIFS(Stats!K:K,Stats!F:F,A6,Stats!E:E,"V")+SUMIFS(Stats!M:M,Stats!G:G,"V",Stats!H:H,A6))/(J6+K6) -> 316.36364
A7: Seattle Seahawks | B7: =COUNTIF($35:$35,A7) -> 1 | C7: =COUNTIF($36:$36,A7) -> 0 | D7: NFC | E7: West | F7: =COUNTIF(Stats!F:F,A7) -> 7 | G7: =COUNTIF(Stats!H:H,A7) -> 10 | H7: =COUNTIFS(Stats!F:F,A7,Stats!E:E,"H") -> 3 | I7: =COUNTIFS(Stats!H:H,A7,Stats!G:G,"H") -> 5 | J7: =F7-H7 -> 4 | K7: =G7-I7 -> 5 | L7: =SUMIFS(Stats!I:I,Stats!F:F,A7)+SUMIFS(Stats!J:J,Stats!H:H,A7) -> 395 | M7: =L7/(F7+G7) -> 23.235294 | N7: =SUMIFS(Stats!I:I,Stats!H:H,A7)+SUMIFS(Stats!J:J,Stats!F:F,A7) -> 366 | O7: =N7/SUM(F7,G7) -> 21.529412 | P7: =L7-N7 -> 29 | Q7: =P7/(F7+G7) -> 1.7058824 | R7: =SUMIFS(Stats!K:K,Stats!F:F,A7)+SUMIFS(Stats!M:M,Stats!H:H,A7) -> 5506 | S7: =SUMIFS(Stats!K:K,Stats!H:H,A7)+SUMIFS(Stats!M:M,Stats!F:F,A7) -> 6445 | T7: =R7/(F7+G7) -> 323.88235 | U7: =S7/(F7+G7) -> 379.11765 | V7: =R7-S7 -> -939 | W7: =T7-U7 -> -55.235294 | X7: =SUMIFS(Stats!I:I,Stats!F:F,A7) -> 239 | Y7: =X7/F7 -> 34.142857 | Z7: =SUMIFS(Stats!J:J,Stats!F:F,A7) -> 139 | AA7: =Z7/F7 -> 19.857143 | AB7: =X7-Z7 -> 100 | AC7: =Y7-AA7 -> 14.285714 | AD7: =SUMIFS(Stats!J:J,Stats!H:H,A7) -> 156 | AE7: =AD7/G7 -> 15.6 | AF7: =SUMIFS(Stats!I:I,Stats!H:H,A7) -> 227 | AG7: =AF7/G7 -> 22.7 | AH7: =AD7-AF7 -> -71 | AI7: =AE7-AG7 -> -7.1 | AJ7: =_xlfn.MINIFS(Stats!O:O,Stats!F:F,A7) -> 7 | AK7: =-_xlfn.MINIFS(Stats!O:O,Stats!H:H,A7) -> -1 | AL7: =_xlfn.MAXIFS(Stats!O:O,Stats!F:F,A7) -> 24 | AM7: =-_xlfn.MAXIFS(Stats!O:O,Stats!H:H,A7) -> -17 | AN7: =_xlfn.MAXIFS(Stats!I:I,Stats!F:F,A7) -> 51 | AO7: =IF(_xlfn.MINIFS(Stats!I:I,Stats!F:F,A7)<_xlfn.MINIFS(Stats!J:J,Stats!H:H,A7),_xlfn.MINIFS(Stats!I:I,Stats!F:F,A7),_xlfn.MINIFS(Stats!J:J,Stats!H:H,A7)) -> 0 | AP7: =IF(_xlfn.MAXIFS(Stats!K:K,Stats!F:F,A7)>_xlfn.MAXIFS(Stats!M:M,Stats!H:H,A7),_xlfn.MAXIFS(Stats!K:K,Stats!F:F,A7),_xlfn.MAXIFS(Stats!M:M,Stats!H:H,A7)) -> 497 | AQ7: =IF(_xlfn.MINIFS(Stats!M:M,Stats!H:H,A7)<_xlfn.MINIFS(Stats!K:K,Stats!F:F,A7),_xlfn.MINIFS(Stats!M:M,Stats!H:H,A7),_xlfn.MINIFS(Stats!K:K,Stats!F:F,A7)) -> 208 | AR7: =SUMIFS(Stats!K:K,Stats!F:F,A7)/F7 -> 364.57143 | AS7: =SUMIFS(Stats!M:M,Stats!F:F,A7)/F7 -> 358.42857 | AT7: =AR7-AS7 -> 6.1428571 | AU7: =SUMIFS(Stats!M:M,Stats!H:H,A7)/G7 -> 295.4 | AV7: =SUMIFS(Stats!K:K,Stats!H:H,A7)/G7 -> 393.6 | AW7: =AU7-AV7 -> -98.2 | AX7: =(SUMIFS(Stats!I:I,Stats!E:E,"H",Stats!F:F,A7)+SUMIFS(Stats!J:J,Stats!H:H,A7,Stats!G:G,"H"))/(H7+I7) -> 25.75 | AY7: =(SUMIFS(Stats!K:K,Stats!F:F,A7,Stats!E:E,"H")+SUMIFS(Stats!M:M,Stats!G:G,"H",Stats!H:H,A7))/(H7+I7) -> 327.5 | AZ7: =(SUMIFS(Stats!I:I,Stats!E:E,"V",Stats!F:F,A7)+SUMIFS(Stats!J:J,Stats!H:H,A7,Stats!G:G,"V"))/(J7+K7) -> 21 | BA7: =(SUMIFS(Stats!K:K,Stats!F:F,A7,Stats!E:E,"V")+SUMIFS(Stats!M:M,Stats!G:G,"V",Stats!H:H,A7))/(J7+K7) -> 320.66667
A8: Arizona Cardinals | B8: =COUNTIF($35:$35,A8) -> 2 | C8: =COUNTIF($36:$36,A8) -> 0 | D8: NFC | E8: West | F8: =COUNTIF(Stats!F:F,A8) -> 11 | G8: =COUNTIF(Stats!H:H,A8) -> 7 | H8: =COUNTIFS(Stats!F:F,A8,Stats!E:E,"H") -> 3 | I8: =COUNTIFS(Stats!H:H,A8,Stats!G:G,"H") -> 5 | J8: =F8-H8 -> 8 | K8: =G8-I8 -> 2 | L8: =SUMIFS(Stats!I:I,Stats!F:F,A8)+SUMIFS(Stats!J:J,Stats!H:H,A8) -> 460 | M8: =L8/(F8+G8) -> 25.555556 | N8: =SUMIFS(Stats!I:I,Stats!H:H,A8)+SUMIFS(Stats!J:J,Stats!F:F,A8) -> 400 | O8: =N8/SUM(F8,G8) -> 22.222222 | P8: =L8-N8 -> 60 | Q8: =P8/(F8+G8) -> 3.3333333 | R8: =SUMIFS(Stats!K:K,Stats!F:F,A8)+SUMIFS(Stats!M:M,Stats!H:H,A8) -> 6535 | S8: =SUMIFS(Stats!K:K,Stats!H:H,A8)+SUMIFS(Stats!M:M,Stats!F:F,A8) -> 5972 | T8: =R8/(F8+G8) -> 363.05556 | U8: =S8/(F8+G8) -> 331.77778 | V8: =R8-S8 -> 563 | W8: =T8-U8 -> 31.277778 | X8: =SUMIFS(Stats!I:I,Stats!F:F,A8) -> 337 | Y8: =X8/F8 -> 30.636364 | Z8: =SUMIFS(Stats!J:J,Stats!F:F,A8) -> 188 | AA8: =Z8/F8 -> 17.090909 | AB8: =X8-Z8 -> 149 | AC8: =Y8-AA8 -> 13.545455 | AD8: =SUMIFS(Stats!J:J,Stats!H:H,A8) -> 123 | AE8: =AD8/G8 -> 17.571429 | AF8: =SUMIFS(Stats!I:I,Stats!H:H,A8) -> 212 | AG8: =AF8/G8 -> 30.285714 | AH8: =AD8-AF8 -> -89 | AI8: =AE8-AG8 -> -12.714286 | AJ8: =_xlfn.MINIFS(Stats!O:O,Stats!F:F,A8) -> 1 | AK8: =-_xlfn.MINIFS(Stats!O:O,Stats!H:H,A8) -> -3 | AL8: =_xlfn.MAXIFS(Stats!O:O,Stats!F:F,A8) -> 26 | AM8: =-_xlfn.MAXIFS(Stats!O:O,Stats!H:H,A8) -> -24 | AN8: =_xlfn.MAXIFS(Stats!I:I,Stats!F:F,A8) -> 38 | AO8: =IF(_xlfn.MINIFS(Stats!I:I,Stats!F:F,A8)<_xlfn.MINIFS(Stats!J:J,Stats!H:H,A8),_xlfn.MINIFS(Stats!I:I,Stats!F:F,A8),_xlfn.MINIFS(Stats!J:J,Stats!H:H,A8)) -> 10 | AP8: =IF(_xlfn.MAXIFS(Stats!K:K,Stats!F:F,A8)>_xlfn.MAXIFS(Stats!M:M,Stats!H:H,A8),_xlfn.MAXIFS(Stats!K:K,Stats!F:F,A8),_xlfn.MAXIFS(Stats!M:M,Stats!H:H,A8)) -> 474 | AQ8: =IF(_xlfn.MINIFS(Stats!M:M,Stats!H:H,A8)<_xlfn.MINIFS(Stats!K:K,Stats!F:F,A8),_xlfn.MINIFS(Stats!M:M,Stats!H:H,A8),_xlfn.MINIFS(Stats!K:K,Stats!F:F,A8)) -> 169 | AR8: =SUMIFS(Stats!K:K,Stats!F:F,A8)/F8 -> 392.81818 | AS8: =SUMIFS(Stats!M:M,Stats!F:F,A8)/F8 -> 313.63636 | AT8: =AR8-AS8 -> 79.181818 | AU8: =SUMIFS(Stats!M:M,Stats!H:H,A8)/G8 -> 316.28571 | AV8: =SUMIFS(Stats!K:K,Stats!H:H,A8)/G8 -> 360.28571 | AW8: =AU8-AV8 -> -44 | AX8: =(SUMIFS(Stats!I:I,Stats!E:E,"H",Stats!F:F,A8)+SUMIFS(Stats!J:J,Stats!H:H,A8,Stats!G:G,"H"))/(H8+I8) -> 22.75 | AY8: =(SUMIFS(Stats!K:K,Stats!F:F,A8,Stats!E:E,"H")+SUMIFS(Stats!M:M,Stats!G:G,"H",Stats!H:H,A8))/(H8+I8) -> 351 | AZ8: =(SUMIFS(Stats!I:I,Stats!E:E,"V",Stats!F:F,A8)+SUMIFS(Stats!J:J,Stats!H:H,A8,Stats!G:G,"V"))/(J8+K8) -> 27.8 | BA8: =(SUMIFS(Stats!K:K,Stats!F:F,A8,Stats!E:E,"V")+SUMIFS(Stats!M:M,Stats!G:G,"V",Stats!H:H,A8))/(J8+K8) -> 372.7
A9: San Francisco 49ers | B9: =COUNTIF($35:$35,A9) -> 0 | C9: =COUNTIF($36:$36,A9) -> 0 | D9: NFC | E9: West | F9: =COUNTIF(Stats!F:F,A9) -> 12 | G9: =COUNTIF(Stats!H:H,A9) -> 8 | H9: =COUNTIFS(Stats!F:F,A9,Stats!E:E,"H") -> 4 | I9: =COUNTIFS(Stats!H:H,A9,Stats!G:G,"H") -> 4 | J9: =F9-H9 -> 8 | K9: =G9-I9 -> 4 | L9: =SUMIFS(Stats!I:I,Stats!F:F,A9)+SUMIFS(Stats!J:J,Stats!H:H,A9) -> 480 | M9: =L9/(F9+G9) -> 24 | N9: =SUMIFS(Stats!I:I,Stats!H:H,A9)+SUMIFS(Stats!J:J,Stats!F:F,A9) -> 412 | O9: =N9/SUM(F9,G9) -> 20.6 | P9: =L9-N9 -> 68 | Q9: =P9/(F9+G9) -> 3.4 | R9: =SUMIFS(Stats!K:K,Stats!F:F,A9)+SUMIFS(Stats!M:M,Stats!H:H,A9) -> 7222 | S9: =SUMIFS(Stats!K:K,Stats!H:H,A9)+SUMIFS(Stats!M:M,Stats!F:F,A9) -> 6236 | T9: =R9/(F9+G9) -> 361.1 | U9: =S9/(F9+G9) -> 311.8 | V9: =R9-S9 -> 986 | W9: =T9-U9 -> 49.3 | X9: =SUMIFS(Stats!I:I,Stats!F:F,A9) -> 329 | Y9: =X9/F9 -> 27.416667 | Z9: =SUMIFS(Stats!J:J,Stats!F:F,A9) -> 206 | AA9: =Z9/F9 -> 17.166667 | AB9: =X9-Z9 -> 123 | AC9: =Y9-AA9 -> 10.25 | AD9: =SUMIFS(Stats!J:J,Stats!H:H,A9) -> 151 | AE9: =AD9/G9 -> 18.875 | AF9: =SUMIFS(Stats!I:I,Stats!H:H,A9) -> 206 | AG9: =AF9/G9 -> 25.75 | AH9: =AD9-AF9 -> -55 | AI9: =AE9-AG9 -> -6.875 | AJ9: =_xlfn.MINIFS(Stats!O:O,Stats!F:F,A9) -> 3 | AK9: =-_xlfn.MINIFS(Stats!O:O,Stats!H:H,A9) -> -2 | AL9: =_xlfn.MAXIFS(Stats!O:O,Stats!F:F,A9) -> 21 | AM9: =-_xlfn.MAXIFS(Stats!O:O,Stats!H:H,A9) -> -14 | AN9: =_xlfn.MAXIFS(Stats!I:I,Stats!F:F,A9) -> 41 | AO9: =IF(_xlfn.MINIFS(Stats!I:I,Stats!F:F,A9)<_xlfn.MINIFS(Stats!J:J,Stats!H:H,A9),_xlfn.MINIFS(Stats!I:I,Stats!F:F,A9),_xlfn.MINIFS(Stats!J:J,Stats!H:H,A9)) -> 10 | AP9: =IF(_xlfn.MAXIFS(Stats!K:K,Stats!F:F,A9)>_xlfn.MAXIFS(Stats!M:M,Stats!H:H,A9),_xlfn.MAXIFS(Stats!K:K,Stats!F:F,A9),_xlfn.MAXIFS(Stats!M:M,Stats!H:H,A9)) -> 467 | AQ9: =IF(_xlfn.MINIFS(Stats!M:M,Stats!H:H,A9)<_xlfn.MINIFS(Stats!K:K,Stats!F:F,A9),_xlfn.MINIFS(Stats!M:M,Stats!H:H,A9),_xlfn.MINIFS(Stats!K:K,Stats!F:F,A9)) -> 212 | AR9: =SUMIFS(Stats!K:K,Stats!F:F,A9)/F9 -> 373 | AS9: =SUMIFS(Stats!M:M,Stats!F:F,A9)/F9 -> 301 | AT9: =AR9-AS9 -> 72 | AU9: =SUMIFS(Stats!M:M,Stats!H:H,A9)/G9 -> 343.25 | AV9: =SUMIFS(Stats!K:K,Stats!H:H,A9)/G9 -> 328 | AW9: =AU9-AV9 -> 15.25 | AX9: =(SUMIFS(Stats!I:I,Stats!E:E,"H",Stats!F:F,A9)+SUMIFS(Stats!J:J,Stats!H:H,A9,Stats!G:G,"H"))/(H9+I9) -> 25.375 | AY9: =(SUMIFS(Stats!K:K,Stats!F:F,A9,Stats!E:E,"H")+SUMIFS(Stats!M:M,Stats!G:G,"H",Stats!H:H,A9))/(H9+I9) -> 367.875 | AZ9: =(SUMIFS(Stats!I:I,Stats!E:E,"V",Stats!F:F,A9)+SUMIFS(Stats!J:J,Stats!H:H,A9,Stats!G:G,"V"))/(J9+K9) -> 23.083333 | BA9: =(SUMIFS(Stats!K:K,Stats!F:F,A9,Stats!E:E,"V")+SUMIFS(Stats!M:M,Stats!G:G,"V",Stats!H:H,A9))/(J9+K9) -> 356.58333
A10: Houston Texans | B10: =COUNTIF($35:$35,A10) -> 0 | C10: =COUNTIF($36:$36,A10) -> 11 | D10: AFC | E10: South | F10: =COUNTIF(Stats!F:F,A10) -> 4 | G10: =COUNTIF(Stats!H:H,A10) -> 13 | H10: =COUNTIFS(Stats!F:F,A10,Stats!E:E,"H") -> 2 | I10: =COUNTIFS(Stats!H:H,A10,Stats!G:G,"H") -> 7 | J10: =F10-H10 -> 2 | K10: =G10-I10 -> 6 | L10: =SUMIFS(Stats!I:I,Stats!F:F,A10)+SUMIFS(Stats!J:J,Stats!H:H,A10) -> 280 | M10: =L10/(F10+G10) -> 16.470588 | N10: =SUMIFS(Stats!I:I,Stats!H:H,A10)+SUMIFS(Stats!J:J,Stats!F:F,A10) -> 452 | O10: =N10/SUM(F10,G10) -> 26.588235 | P10: =L10-N10 -> -172 | Q10: =P10/(F10+G10) -> -10.117647 | R10: =SUMIFS(Stats!K:K,Stats!F:F,A10)+SUMIFS(Stats!M:M,Stats!H:H,A10) -> 4727 | S10: =SUMIFS(Stats!K:K,Stats!H:H,A10)+SUMIFS(Stats!M:M,Stats!F:F,A10) -> 6535 | T10: =R10/(F10+G10) -> 278.05882 | U10: =S10/(F10+G10) -> 384.41176 | V10: =R10-S10 -> -1808 | W10: =T10-U10 -> -106.35294 | X10: =SUMIFS(Stats!I:I,Stats!F:F,A10) -> 130 | Y10: =X10/F10 -> 32.5 | Z10: =SUMIFS(Stats!J:J,Stats!F:F,A10) -> 79 | AA10: =Z10/F10 -> 19.75 | AB10: =X10-Z10 -> 51 | AC10: =Y10-AA10 -> 12.75 | AD10: =SUMIFS(Stats!J:J,Stats!H:H,A10) -> 150 | AE10: =AD10/G10 -> 11.538462 | AF10: =SUMIFS(Stats!I:I,Stats!H:H,A10) -> 373 | AG10: =AF10/G10 -> 28.692308 | AH10: =AD10-AF10 -> -223 | AI10: =AE10-AG10 -> -17.153846 | AJ10: =_xlfn.MINIFS(Stats!O:O,Stats!F:F,A10) -> 9 | AK10: =-_xlfn.MINIFS(Stats!O:O,Stats!H:H,A10) -> -3 | AL10: =_xlfn.MAXIFS(Stats!O:O,Stats!F:F,A10) -> 16 | AM10: =-_xlfn.MAXIFS(Stats!O:O,Stats!H:H,A10) -> -40 | AN10: =_xlfn.MAXIFS(Stats!I:I,Stats!F:F,A10) -> 41 | AO10: =IF(_xlfn.MINIFS(Stats!I:I,Stats!F:F,A10)<_xlfn.MINIFS(Stats!J:J,Stats!H:H,A10),_xlfn.MINIFS(Stats!I:I,Stats!F:F,A10),_xlfn.MINIFS(Stats!J:J,Stats!H:H,A10)) -> 0 | AP10: =IF(_xlfn.MAXIFS(Stats!K:K,Stats!F:F,A10)>_xlfn.MAXIFS(Stats!M:M,Stats!H:H,A10),_xlfn.MAXIFS(Stats!K:K,Stats!F:F,A10),_xlfn.MAXIFS(Stats!M:M,Stats!H:H,A10)) -> 449 | AQ10: =IF(_xlfn.MINIFS(Stats!M:M,Stats!H:H,A10)<_xlfn.MINIFS(Stats!K:K,Stats!F:F,A10),_xlfn.MINIFS(Stats!M:M,Stats!H:H,A10),_xlfn.MINIFS(Stats!K:K,Stats!F:F,A10)) -> 109 | AR10: =SUMIFS(Stats!K:K,Stats!F:F,A10)/F10 -> 339.25 | AS10: =SUMIFS(Stats!M:M,Stats!F:F,A10)/F10 -> 382 | AT10: =AR10-AS10 -> -42.75 | AU10: =SUMIFS(Stats!M:M,Stats!H:H,A10)/G10 -> 259.23077 | AV10: =SUMIFS(Stats!K:K,Stats!H:H,A10)/G10 -> 385.15385 | AW10: =AU10-AV10 -> -125.92308 | AX10: =(SUMIFS(Stats!I:I,Stats!E:E,"H",Stats!F:F,A10)+SUMIFS(Stats!J:J,Stats!H:H,A10,Stats!G:G,"H"))/(H10+I10) -> 20.333333 | AY10: =(SUMIFS(Stats!K:K,Stats!F:F,A10,Stats!E:E,"H")+SUMIFS(Stats!M:M,Stats!G:G,"H",Stats!H:H,A10))/(H10+I10) -> 315.33333 | AZ10: =(SUMIFS(Stats!I:I,Stats!E:E,"V",Stats!F:F,A10)+SUMIFS(Stats!J:J,Stats!H:H,A10,Stats!G:G,"V"))/(J10+K10) -> 12.125 | BA10: =(SUMIFS(Stats!K:K,Stats!F:F,A10,Stats!E:E,"V")+SUMIFS(Stats!M:M,Stats!G:G,"V",Stats!H:H,A10))/(J10+K10) -> 236.125
A11: Los Angeles Chargers | B11: =COUNTIF($35:$35,A11) -> 0 | C11: =COUNTIF($36:$36,A11) -> 1 | D11: AFC | E11: West | F11: =COUNTIF(Stats!F:F,A11) -> 9 | G11: =COUNTIF(Stats!H:H,A11) -> 8 | H11: =COUNTIFS(Stats!F:F,A11,Stats!E:E,"H") -> 5 | I11: =COUNTIFS(Stats!H:H,A11,Stats!G:G,"H") -> 4 | J11: =F11-H11 -> 4 | K11: =G11-I11 -> 4 | L11: =SUMIFS(Stats!I:I,Stats!F:F,A11)+SUMIFS(Stats!J:J,Stats!H:H,A11) -> 474 | M11: =L11/(F11+G11) -> 27.882353 | N11: =SUMIFS(Stats!I:I,Stats!H:H,A11)+SUMIFS(Stats!J:J,Stats!F:F,A11) -> 459 | O11: =N11/SUM(F11,G11) -> 27 | P11: =L11-N11 -> 15 | Q11: =P11/(F11+G11) -> 0.88235294 | R11: =SUMIFS(Stats!K:K,Stats!F:F,A11)+SUMIFS(Stats!M:M,Stats!H:H,A11) -> 6634 | S11: =SUMIFS(Stats!K:K,Stats!H:H,A11)+SUMIFS(Stats!M:M,Stats!F:F,A11) -> 6122 | T11: =R11/(F11+G11) -> 390.23529 | U11: =S11/(F11+G11) -> 360.11765 | V11: =R11-S11 -> 512 | W11: =T11-U11 -> 30.117647 | X11: =SUMIFS(Stats!I:I,Stats!F:F,A11) -> 305 | Y11: =X11/F11 -> 33.888889 | Z11: =SUMIFS(Stats!J:J,Stats!F:F,A11) -> 213 | AA11: =Z11/F11 -> 23.666667 | AB11: =X11-Z11 -> 92 | AC11: =Y11-AA11 -> 10.222222 | AD11: =SUMIFS(Stats!J:J,Stats!H:H,A11) -> 169 | AE11: =AD11/G11 -> 21.125 | AF11: =SUMIFS(Stats!I:I,Stats!H:H,A11) -> 246 | AG11: =AF11/G11 -> 30.75 | AH11: =AD11-AF11 -> -77 | AI11: =AE11-AG11 -> -9.625 | AJ11: =_xlfn.MINIFS(Stats!O:O,Stats!F:F,A11) -> 3 | AK11: =-_xlfn.MINIFS(Stats!O:O,Stats!H:H,A11) -> -3 | AL11: =_xlfn.MAXIFS(Stats!O:O,Stats!F:F,A11) -> 21 | AM11: =-_xlfn.MAXIFS(Stats!O:O,Stats!H:H,A11) -> -28 | AN11: =_xlfn.MAXIFS(Stats!I:I,Stats!F:F,A11) -> 47 | AO11: =IF(_xlfn.MINIFS(Stats!I:I,Stats!F:F,A11)<_xlfn.MINIFS(Stats!J:J,Stats!H:H,A11),_xlfn.MINIFS(Stats!I:I,Stats!F:F,A11),_xlfn.MINIFS(Stats!J:J,Stats!H:H,A11)) -> 6 | AP11: =IF(_xlfn.MAXIFS(Stats!K:K,Stats!F:F,A11)>_xlfn.MAXIFS(Stats!M:M,Stats!H:H,A11),_xlfn.MAXIFS(Stats!K:K,Stats!F:F,A11),_xlfn.MAXIFS(Stats!M:M,Stats!H:H,A11)) -> 533 | AQ11: =IF(_xlfn.MINIFS(Stats!M:M,Stats!H:H,A11)<_xlfn.MINIFS(Stats!K:K,Stats!F:F,A11),_xlfn.MINIFS(Stats!M:M,Stats!H:H,A11),_xlfn.MINIFS(Stats!K:K,Stats!F:F,A11)) -> 208 | AR11: =SUMIFS(Stats!K:K,Stats!F:F,A11)/F11 -> 417.11111 | AS11: =SUMIFS(Stats!M:M,Stats!F:F,A11)/F11 -> 340.22222 | AT11: =AR11-AS11 -> 76.888889 | AU11: =SUMIFS(Stats!M:M,Stats!H:H,A11)/G11 -> 360 | AV11: =SUMIFS(Stats!K:K,Stats!H:H,A11)/G11 -> 382.5 | AW11: =AU11-AV11 -> -22.5 | AX11: =(SUMIFS(Stats!I:I,Stats!E:E,"H",Stats!F:F,A11)+SUMIFS(Stats!J:J,Stats!H:H,A11,Stats!G:G,"H"))/(H11+I11) -> 30.666667 | AY11: =(SUMIFS(Stats!K:K,Stats!F:F,A11,Stats!E:E,"H")+SUMIFS(Stats!M:M,Stats!G:G,"H",Stats!H:H,A11))/(H11+I11) -> 403.11111 | AZ11: =(SUMIFS(Stats!I:I,Stats!E:E,"V",Stats!F:F,A11)+SUMIFS(Stats!J:J,Stats!H:H,A11,Stats!G:G,"V"))/(J11+K11) -> 24.75 | BA11: =(SUMIFS(Stats!K:K,Stats!F:F,A11,Stats!E:E,"V")+SUMIFS(Stats!M:M,Stats!G:G,"V",Stats!H:H,A11))/(J11+K11) -> 375.75
A12: Kansas City Chiefs | B12: =COUNTIF($35:$35,A12) -> 7 | C12: =COUNTIF($36:$36,A12) -> 0 | D12: AFC | E12: West | F12: =COUNTIF(Stats!F:F,A12) -> 14 | G12: =COUNTIF(Stats!H:H,A12) -> 6 | H12: =COUNTIFS(Stats!F:F,A12,Stats!E:E,"H") -> 9 | I12: =COUNTIFS(Stats!H:H,A12,Stats!G:G,"H") -> 3 | J12: =F12-H12 -> 5 | K12: =G12-I12 -> 3 | L12: =SUMIFS(Stats!I:I,Stats!F:F,A12)+SUMIFS(Stats!J:J,Stats!H:H,A12) -> 588 | M12: =L12/(F12+G12) -> 29.4 | N12: =SUMIFS(Stats!I:I,Stats!H:H,A12)+SUMIFS(Stats!J:J,Stats!F:F,A12) -> 448 | O12: =N12/SUM(F12,G12) -> 22.4 | P12: =L12-N12 -> 140 | Q12: =P12/(F12+G12) -> 7 | R12: =SUMIFS(Stats!K:K,Stats!F:F,A12)+SUMIFS(Stats!M:M,Stats!H:H,A12) -> 8151 | S12: =SUMIFS(Stats!K:K,Stats!H:H,A12)+SUMIFS(Stats!M:M,Stats!F:F,A12) -> 7310 | T12: =R12/(F12+G12) -> 407.55 | U12: =S12/(F12+G12) -> 365.5 | V12: =R12-S12 -> 841 | W12: =T12-U12 -> 42.05 | X12: =SUMIFS(Stats!I:I,Stats!F:F,A12) -> 451 | Y12: =X12/F12 -> 32.214286 | Z12: =SUMIFS(Stats!J:J,Stats!F:F,A12) -> 256 | AA12: =Z12/F12 -> 18.285714 | AB12: =X12-Z12 -> 195 | AC12: =Y12-AA12 -> 13.928571 | AD12: =SUMIFS(Stats!J:J,Stats!H:H,A12) -> 137 | AE12: =AD12/G12 -> 22.833333 | AF12: =SUMIFS(Stats!I:I,Stats!H:H,A12) -> 192 | AG12: =AF12/G12 -> 32 | AH12: =AD12-AF12 -> -55 | AI12: =AE12-AG12 -> -9.1666667 | AJ12: =_xlfn.MINIFS(Stats!O:O,Stats!F:F,A12) -> 3 | AK12: =-_xlfn.MINIFS(Stats!O:O,Stats!H:H,A12) -> -1 | AL12: =_xlfn.MAXIFS(Stats!O:O,Stats!F:F,A12) -> 39 | AM12: =-_xlfn.MAXIFS(Stats!O:O,Stats!H:H,A12) -> -24 | AN12: =_xlfn.MAXIFS(Stats!I:I,Stats!F:F,A12) -> 48 | AO12: =IF(_xlfn.MINIFS(Stats!I:I,Stats!F:F,A12)<_xlfn.MINIFS(Stats!J:J,Stats!H:H,A12),_xlfn.MINIFS(Stats!I:I,Stats!F:F,A12),_xlfn.MINIFS(Stats!J:J,Stats!H:H,A12)) -> 3 | AP12: =IF(_xlfn.MAXIFS(Stats!K:K,Stats!F:F,A12)>_xlfn.MAXIFS(Stats!M:M,Stats!H:H,A12),_xlfn.MAXIFS(Stats!K:K,Stats!F:F,A12),_xlfn.MAXIFS(Stats!M:M,Stats!H:H,A12)) -> 552 | AQ12: =IF(_xlfn.MINIFS(Stats!M:M,Stats!H:H,A12)<_xlfn.MINIFS(Stats!K:K,Stats!F:F,A12),_xlfn.MINIFS(Stats!M:M,Stats!H:H,A12),_xlfn.MINIFS(Stats!K:K,Stats!F:F,A12)) -> 237 | AR12: =SUMIFS(Stats!K:K,Stats!F:F,A12)/F12 -> 413.85714 | AS12: =SUMIFS(Stats!M:M,Stats!F:F,A12)/F12 -> 345.57143 | AT12: =AR12-AS12 -> 68.285714 | AU12: =SUMIFS(Stats!M:M,Stats!H:H,A12)/G12 -> 392.83333 | AV12: =SUMIFS(Stats!K:K,Stats!H:H,A12)/G12 -> 412 | AW12: =AU12-AV12 -> -19.166667 | AX12: =(SUMIFS(Stats!I:I,Stats!E:E,"H",Stats!F:F,A12)+SUMIFS(Stats!J:J,Stats!H:H,A12,Stats!G:G,"H"))/(H12+I12) -> 28.583333 | AY12: =(SUMIFS(Stats!K:K,Stats!F:F,A12,Stats!E:E,"H")+SUMIFS(Stats!M:M,Stats!G:G,"H",Stats!H:H,A12))/(H12+I12) -> 385.5 | AZ12: =(SUMIFS(Stats!I:I,Stats!E:E,"V",Stats!F:F,A12)+SUMIFS(Stats!J:J,Stats!H:H,A12,Stats!G:G,"V"))/(J12+K12) -> 30.625 | BA12: =(SUMIFS(Stats!K:K,Stats!F:F,A12,Stats!E:E,"V")+SUMIFS(Stats!M:M,Stats!G:G,"V",Stats!H:H,A12))/(J12+K12) -> 440.625
A13: Denver Broncos | B13: =COUNTIF($35:$35,A13) -> 1 | C13: =COUNTIF($36:$36,A13) -> 0 | D13: AFC | E13: West | F13: =COUNTIF(Stats!F:F,A13) -> 7 | G13: =COUNTIF(Stats!H:H,A13) -> 10 | H13: =COUNTIFS(Stats!F:F,A13,Stats!E:E,"H") -> 4 | I13: =COUNTIFS(Stats!H:H,A13,Stats!G:G,"H") -> 5 | J13: =F13-H13 -> 3 | K13: =G13-I13 -> 5 | L13: =SUMIFS(Stats!I:I,Stats!F:F,A13)+SUMIFS(Stats!J:J,Stats!H:H,A13) -> 335 | M13: =L13/(F13+G13) -> 19.705882 | N13: =SUMIFS(Stats!I:I,Stats!H:H,A13)+SUMIFS(Stats!J:J,Stats!F:F,A13) -> 322 | O13: =N13/SUM(F13,G13) -> 18.941176 | P13: =L13-N13 -> 13 | Q13: =P13/(F13+G13) -> 0.76470588 | R13: =SUMIFS(Stats!K:K,Stats!F:F,A13)+SUMIFS(Stats!M:M,Stats!H:H,A13) -> 5618 | S13: =SUMIFS(Stats!K:K,Stats!H:H,A13)+SUMIFS(Stats!M:M,Stats!F:F,A13) -> 5544 | T13: =R13/(F13+G13) -> 330.47059 | U13: =S13/(F13+G13) -> 326.11765 | V13: =R13-S13 -> 74 | W13: =T13-U13 -> 4.3529412 | X13: =SUMIFS(Stats!I:I,Stats!F:F,A13) -> 189 | Y13: =X13/F13 -> 27 | Z13: =SUMIFS(Stats!J:J,Stats!F:F,A13) -> 75 | AA13: =Z13/F13 -> 10.714286 | AB13: =X13-Z13 -> 114 | AC13: =Y13-AA13 -> 16.285714 | AD13: =SUMIFS(Stats!J:J,Stats!H:H,A13) -> 146 | AE13: =AD13/G13 -> 14.6 | AF13: =SUMIFS(Stats!I:I,Stats!H:H,A13) -> 247 | AG13: =AF13/G13 -> 24.7 | AH13: =AD13-AF13 -> -101 | AI13: =AE13-AG13 -> -10.1 | AJ13: =_xlfn.MINIFS(Stats!O:O,Stats!F:F,A13) -> 7 | AK13: =-_xlfn.MINIFS(Stats!O:O,Stats!H:H,A13) -> -3 | AL13: =_xlfn.MAXIFS(Stats!O:O,Stats!F:F,A13) -> 28 | AM13: =-_xlfn.MAXIFS(Stats!O:O,Stats!H:H,A13) -> -21 | AN13: =_xlfn.MAXIFS(Stats!I:I,Stats!F:F,A13) -> 38 | AO13: =IF(_xlfn.MINIFS(Stats!I:I,Stats!F:F,A13)<_xlfn.MINIFS(Stats!J:J,Stats!H:H,A13),_xlfn.MINIFS(Stats!I:I,Stats!F:F,A13),_xlfn.MINIFS(Stats!J:J,Stats!H:H,A13)) -> 7 | AP13: =IF(_xlfn.MAXIFS(Stats!K:K,Stats!F:F,A13)>_xlfn.MAXIFS(Stats!M:M,Stats!H:H,A13),_xlfn.MAXIFS(Stats!K:K,Stats!F:F,A13),_xlfn.MAXIFS(Stats!M:M,Stats!H:H,A13)) -> 421 | AQ13: =IF(_xlfn.MINIFS(Stats!M:M,Stats!H:H,A13)<_xlfn.MINIFS(Stats!K:K,Stats!F:F,A13),_xlfn.MINIFS(Stats!M:M,Stats!H:H,A13),_xlfn.MINIFS(Stats!K:K,Stats!F:F,A13)) -> 158 | AR13: =SUMIFS(Stats!K:K,Stats!F:F,A13)/F13 -> 357.28571 | AS13: =SUMIFS(Stats!M:M,Stats!F:F,A13)/F13 -> 281.42857 | AT13: =AR13-AS13 -> 75.857143 | AU13: =SUMIFS(Stats!M:M,Stats!H:H,A13)/G13 -> 311.7 | AV13: =SUMIFS(Stats!K:K,Stats!H:H,A13)/G13 -> 357.4 | AW13: =AU13-AV13 -> -45.7 | AX13: =(SUMIFS(Stats!I:I,Stats!E:E,"H",Stats!F:F,A13)+SUMIFS(Stats!J:J,Stats!H:H,A13,Stats!G:G,"H"))/(H13+I13) -> 20.777778 | AY13: =(SUMIFS(Stats!K:K,Stats!F:F,A13,Stats!E:E,"H")+SUMIFS(Stats!M:M,Stats!G:G,"H",Stats!H:H,A13))/(H13+I13) -> 323.88889 | AZ13: =(SUMIFS(Stats!I:I,Stats!E:E,"V",Stats!F:F,A13)+SUMIFS(Stats!J:J,Stats!H:H,A13,Stats!G:G,"V"))/(J13+K13) -> 18.5 | BA13: =(SUMIFS(Stats!K:K,Stats!F:F,A13,Stats!E:E,"V")+SUMIFS(Stats!M:M,Stats!G:G,"V",Stats!H:H,A13))/(J13+K13) -> 337.875
... A33: Detroit Lions | B33: =COUNTIF($35:$35,A33) -> 1 | C33: =COUNTIF($36:$36,A33) -> 3 | D33: NFC | E33: North | F33: =COUNTIF(Stats!F:F,A33) -> 3 | G33: =COUNTIF(Stats!H:H,A33) -> 14 | H33: =COUNTIFS(Stats!F:F,A33,Stats!E:E,"H") -> 3 | I33: =COUNTIFS(Stats!H:H,A33,Stats!G:G,"H") -> 5 | J33: =F33-H33 -> 0 | K33: =G33-I33 -> 9 | L33: =SUMIFS(Stats!I:I,Stats!F:F,A33)+SUMIFS(Stats!J:J,Stats!H:H,A33) -> 325 | M33: =L33/(F33+G33) -> 19.117647 | N33: =SUMIFS(Stats!I:I,Stats!H:H,A33)+SUMIFS(Stats!J:J,Stats!F:F,A33) -> 467 | O33: =N33/SUM(F33,G33) -> 27.470588 | P33: =L33-N33 -> -142 | Q33: =P33/(F33+G33) -> -8.3529412 | R33: =SUMIFS(Stats!K:K,Stats!F:F,A33)+SUMIFS(Stats!M:M,Stats!H:H,A33) -> 5484 | S33: =SUMIFS(Stats!K:K,Stats!H:H,A33)+SUMIFS(Stats!M:M,Stats!F:F,A33) -> 6456 | T33: =R33/(F33+G33) -> 322.58824 | U33: =S33/(F33+G33) -> 379.76471 | V33: =R33-S33 -> -972 | W33: =T33-U33 -> -57.176471 | X33: =SUMIFS(Stats!I:I,Stats!F:F,A33) -> 96 | Y33: =X33/F33 -> 32 | Z33: =SUMIFS(Stats!J:J,Stats!F:F,A33) -> 69 | AA33: =Z33/F33 -> 23 | AB33: =X33-Z33 -> 27 | AC33: =Y33-AA33 -> 9 | AD33: =SUMIFS(Stats!J:J,Stats!H:H,A33) -> 229 | AE33: =AD33/G33 -> 16.357143 | AF33: =SUMIFS(Stats!I:I,Stats!H:H,A33) -> 398 | AG33: =AF33/G33 -> 28.428571 | AH33: =AD33-AF33 -> -169 | AI33: =AE33-AG33 -> -12.071429 | AJ33: =_xlfn.MINIFS(Stats!O:O,Stats!F:F,A33) -> 2 | AK33: =-_xlfn.MINIFS(Stats!O:O,Stats!H:H,A33) -> -2 | AL33: =_xlfn.MAXIFS(Stats!O:O,Stats!F:F,A33) -> 18 | AM33: =-_xlfn.MAXIFS(Stats!O:O,Stats!H:H,A33) -> -38 | AN33: =_xlfn.MAXIFS(Stats!I:I,Stats!F:F,A33) -> 37 | AO33: =IF(_xlfn.MINIFS(Stats!I:I,Stats!F:F,A33)<_xlfn.MINIFS(Stats!J:J,Stats!H:H,A33),_xlfn.MINIFS(Stats!I:I,Stats!F:F,A33),_xlfn.MINIFS(Stats!J:J,Stats!H:H,A33)) -> 6 | AP33: =IF(_xlfn.MAXIFS(Stats!K:K,Stats!F:F,A33)>_xlfn.MAXIFS(Stats!M:M,Stats!H:H,A33),_xlfn.MAXIFS(Stats!K:K,Stats!F:F,A33),_xlfn.MAXIFS(Stats!M:M,Stats!H:H,A33)) -> 430 | AQ33: =IF(_xlfn.MINIFS(Stats!M:M,Stats!H:H,A33)<_xlfn.MINIFS(Stats!K:K,Stats!F:F,A33),_xlfn.MINIFS(Stats!M:M,Stats!H:H,A33),_xlfn.MINIFS(Stats!K:K,Stats!F:F,A33)) -> 228 | AR33: =SUMIFS(Stats!K:K,Stats!F:F,A33)/F33 -> 371.33333 | AS33: =SUMIFS(Stats!M:M,Stats!F:F,A33)/F33 -> 400.66667 | AT33: =AR33-AS33 -> -29.333333 | AU33: =SUMIFS(Stats!M:M,Stats!H:H,A33)/G33 -> 312.14286 | AV33: =SUMIFS(Stats!K:K,Stats!H:H,A33)/G33 -> 375.28571 | AW33: =AU33-AV33 -> -63.142857 | AX33: =(SUMIFS(Stats!I:I,Stats!E:E,"H",Stats!F:F,A33)+SUMIFS(Stats!J:J,Stats!H:H,A33,Stats!G:G,"H"))/(H33+I33) -> 22.125 | AY33: =(SUMIFS(Stats!K:K,Stats!F:F,A33,Stats!E:E,"H")+SUMIFS(Stats!M:M,Stats!G:G,"H",Stats!H:H,A33))/(H33+I33) -> 315.5 | AZ33: =(SUMIFS(Stats!I:I,Stats!E:E,"V",Stats!F:F,A33)+SUMIFS(Stats!J:J,Stats!H:H,A33,Stats!G:G,"V"))/(J33+K33) -> 16.444444 | BA33: =(SUMIFS(Stats!K:K,Stats!F:F,A33,Stats!E:E,"V")+SUMIFS(Stats!M:M,Stats!G:G,"V",Stats!H:H,A33))/(J33+K33) -> 328.88889
A35: Los Angeles Rams | B35: Green Bay Packers | C35: San Franciso 49ers | F35: =INDEX($A:$A,MATCH(MAX(F$2:F$33),F:F,0)) -> Los Angeles Rams | G35: =INDEX($A:$A,MATCH(MIN(G$2:G$33),G:G,0)) -> Tampa Bay Buccaneers | H35: =INDEX($A:$A,MATCH(MAX(H$2:H$33),H:H,0)) -> Kansas City Chiefs | I35: =INDEX($A:$A,MATCH(MIN(I$2:I$33),I:I,0)) -> Green Bay Packers | J35: =INDEX($A:$A,MATCH(MAX(J$2:J$33),J:J,0)) -> Arizona Cardinals | K35: =INDEX($A:$A,MATCH(MIN(K$2:K$33),K:K,0)) -> Arizona Cardinals | L35: =INDEX($A:$A,MATCH(MAX(L$2:L$33),L:L,0)) -> Kansas City Chiefs | M35: =INDEX($A:$A,MATCH(MAX(M$2:M$33),M:M,0)) -> Dallas Cowboys | N35: =INDEX($A:$A,MATCH(MIN(N$2:N$33),N:N,0)) -> Denver Broncos | O35: =INDEX($A:$A,MATCH(MIN(O$2:O$33),O:O,0)) -> Buffalo Bills | P35: =INDEX($A:$A,MATCH(MAX(P$2:P$33),P:P,0)) -> Buffalo Bills | Q35: =INDEX($A:$A,MATCH(MAX(Q$2:Q$33),Q:Q,0)) -> Buffalo Bills | R35: =INDEX($A:$A,MATCH(MAX(R$2:R$33),R:R,0)) -> Kansas City Chiefs | S35: =INDEX($A:$A,MATCH(MIN(S$2:S$33),S:S,0)) -> Carolina Panthers | T35: =INDEX($A:$A,MATCH(MAX(T$2:T$33),T:T,0)) -> Kansas City Chiefs | U35: =INDEX($A:$A,MATCH(MIN(U$2:U$33),U:U,0)) -> Buffalo Bills | V35: =INDEX($A:$A,MATCH(MAX(V$2:V$33),V:V,0)) -> Buffalo Bills | W35: =INDEX($A:$A,MATCH(MAX(W$2:W$33),W:W,0)) -> Buffalo Bills | X35: =INDEX($A:$A,MATCH(MAX(X$2:X$33),X:X,0)) -> Tampa Bay Buccaneers | Y35: =INDEX($A:$A,MATCH(MAX(Y$2:Y$33),Y:Y,0)) -> Buffalo Bills | Z35: =INDEX($A:$A,MATCH(MIN(Z$2:Z$33),Z:Z,0)) -> Jacksonville Jaguars | AA35: =INDEX($A:$A,MATCH(MIN(AA$2:AA$33),AA:AA,0)) -> Carolina Panthers | AB35: =INDEX($A:$A,MATCH(MAX(AB$2:AB$33),AB:AB,0)) -> Buffalo Bills | AC35: =INDEX($A:$A,MATCH(MAX(AC$2:AC$33),AC:AC,0)) -> Buffalo Bills | AD35: =INDEX($A:$A,MATCH(MAX(AD$2:AD$33),AD:AD,0)) -> Detroit Lions | AE35: =INDEX($A:$A,MATCH(MAX(AE$2:AE$33),AE:AE,0)) -> Kansas City Chiefs | AF35: =INDEX($A:$A,MATCH(MIN(AF$2:AF$33),AF:AF,0)) -> Green Bay Packers | AG35: =INDEX($A:$A,MATCH(MIN(AG$2:AG$33),AG:AG,0)) -> Seattle Seahawks | AH35: =INDEX($A:$A,MATCH(MAX(AH$2:AH$33),AH:AH,0)) -> Dallas Cowboys | AI35: =INDEX($A:$A,MATCH(MAX(AI$2:AI$33),AI:AI,0)) -> Dallas Cowboys | AJ35: =INDEX($A:$A,MATCH(MAX(AJ$2:AJ$33),AJ:AJ,0)) -> Buffalo Bills | AL35: =INDEX($A:$A,MATCH(MAX(AL$2:AL$33),AL:AL,0)) -> Dallas Cowboys | AM35: =INDEX($A:$A,MATCH(MIN(AM$2:AM$33),AM:AM,0)) -> Washington Football Team | AN35: =INDEX($A:$A,MATCH(MAX(AN$2:AN$33),AN:AN,0)) -> Dallas Cowboys | AO35: =INDEX($A:$A,MATCH(MAX(AO$2:AO$33),AO:AO,0)) -> Cincinnati Bengals | AP35: =INDEX($A:$A,MATCH(MAX(AP$2:AP$33),AP:AP,0)) -> Cincinnati Bengals | AQ35: =INDEX($A:$A,MATCH(MAX(AQ$2:AQ$33),AQ:AQ,0)) -> Baltimore Ravens | AR35: =INDEX($A:$A,MATCH(MAX(AR$2:AR$33),AR:AR,0)) -> Dallas Cowboys | AS35: =INDEX($A:$A,MATCH(MIN(AS$2:AS$33),AS:AS,0)) -> Carolina Panthers | AT35: =INDEX($A:$A,MATCH(MAX(AT$2:AT$33),AT:AT,0)) -> Carolina Panthers | AU35: =INDEX($A:$A,MATCH(MAX(AU$2:AU$33),AU:AU,0)) -> Kansas City Chiefs | AV35: =INDEX($A:$A,MATCH(MIN(AV$2:AV$33),AV:AV,0)) -> Tennessee Titans | AW35: =INDEX($A:$A,MATCH(MAX(AW$2:AW$33),AW:AW,0)) -> Tennessee Titans | AX35: =INDEX($A:$A,MATCH(MAX(AX$2:AX$33),AX:AX,0)) -> Dallas Cowboys | AY35: =INDEX($A:$A,MATCH(MAX(AY$2:AY$33),AY:AY,0)) -> Tampa Bay Buccaneers | AZ35: =INDEX($A:$A,MATCH(MAX(AZ$2:AZ$33),AZ:AZ,0)) -> Buffalo Bills | BA35: =INDEX($A:$A,MATCH(MAX(BA$2:BA$33),BA:BA,0)) -> Kansas City Chiefs
A36: Detroit Lions | B36: Houston Texans | F36: =INDEX($A:$A,MATCH(MIN(F$2:F$33),F:F,0)) -> Jacksonville Jaguars | G36: =INDEX($A:$A,MATCH(MAX(G$2:G$33),G:G,0)) -> Jacksonville Jaguars | H36: =INDEX($A:$A,MATCH(MIN(H$2:H$33),H:H,0)) -> Carolina Panthers | I36: =INDEX($A:$A,MATCH(MAX(I$2:I$33),I:I,0)) -> Houston Texans | J36: =INDEX($A:$A,MATCH(MIN(J$2:J$33),J:J,0)) -> Jacksonville Jaguars | K36: =INDEX($A:$A,MATCH(MAX(K$2:K$33),K:K,0)) -> Detroit Lions | L36: =INDEX($A:$A,MATCH(MIN(L$2:L$33),L:L,0)) -> Jacksonville Jaguars | M36: =INDEX($A:$A,MATCH(MIN(M$2:M$33),M:M,0)) -> Jacksonville Jaguars | N36: =INDEX($A:$A,MATCH(MAX(N$2:N$33),N:N,0)) -> New York Jets | O36: =INDEX($A:$A,MATCH(MAX(O$2:O$33),O:O,0)) -> New York Jets | P36: =INDEX($A:$A,MATCH(MIN(P$2:P$33),P:P,0)) -> Jacksonville Jaguars | Q36: =INDEX($A:$A,MATCH(MIN(Q$2:Q$33),Q:Q,0)) -> Jacksonville Jaguars | R36: =INDEX($A:$A,MATCH(MIN(R$2:R$33),R:R,0)) -> Houston Texans | S36: =INDEX($A:$A,MATCH(MAX(S$2:S$33),S:S,0)) -> Cincinnati Bengals | T36: =INDEX($A:$A,MATCH(MIN(T$2:T$33),T:T,0)) -> Houston Texans | U36: =INDEX($A:$A,MATCH(MAX(U$2:U$33),U:U,0)) -> New York Jets | V36: =INDEX($A:$A,MATCH(MIN(V$2:V$33),V:V,0)) -> Houston Texans | W36: =INDEX($A:$A,MATCH(MIN(W$2:W$33),W:W,0)) -> Houston Texans | X36: =INDEX($A:$A,MATCH(MIN(X$2:X$33),X:X,0)) -> Jacksonville Jaguars | Y36: =INDEX($A:$A,MATCH(MIN(Y$2:Y$33),Y:Y,0)) -> Jacksonville Jaguars | Z36: =INDEX($A:$A,MATCH(MAX(Z$2:Z$33),Z:Z,0)) -> Los Angeles Rams | AA36: =INDEX($A:$A,MATCH(MAX(AA$2:AA$33),AA:AA,0)) -> Los Angeles Chargers | AB36: =INDEX($A:$A,MATCH(MIN(AB$2:AB$33),AB:AB,0)) -> New York Jets | AC36: =INDEX($A:$A,MATCH(MIN(AC$2:AC$33),AC:AC,0)) -> New York Jets | AD36: =INDEX($A:$A,MATCH(MIN(AD$2:AD$33),AD:AD,0)) -> Green Bay Packers | AE36: =INDEX($A:$A,MATCH(MIN(AE$2:AE$33),AE:AE,0)) -> Houston Texans | AF36: =INDEX($A:$A,MATCH(MAX(AF$2:AF$33),AF:AF,0)) -> Jacksonville Jaguars | AG36: =INDEX($A:$A,MATCH(MAX(AG$2:AG$33),AG:AG,0)) -> Pittsburgh Steelers | AH36: =INDEX($A:$A,MATCH(MIN(AH$2:AH$33),AH:AH,0)) -> Jacksonville Jaguars | AI36: =INDEX($A:$A,MATCH(MIN(AI$2:AI$33),AI:AI,0)) -> Atlanta Falcons | AL36: =INDEX($A:$A,MATCH(MIN(AL$2:AL$33),AL:AL,0)) -> New York Jets | AM36: =INDEX($A:$A,MATCH(MAX(AM$2:AM$33),AM:AM,0)) -> Tampa Bay Buccaneers | AN36: =INDEX($A:$A,MATCH(MIN(AN$2:AN$33),AN:AN,0)) -> Jacksonville Jaguars | AP36: =INDEX($A:$A,MATCH(MIN(AP$2:AP$33),AP:AP,0)) -> Pittsburgh Steelers | AQ36: =INDEX($A:$A,MATCH(MIN(AQ$2:AQ$33),AQ:AQ,0)) -> Chicago Bears | AR36: =INDEX($A:$A,MATCH(MIN(AR$2:AR$33),AR:AR,0)) -> Chicago Bears | AS36: =INDEX($A:$A,MATCH(MAX(AS$2:AS$33),AS:AS,0)) -> Detroit Lions | AT36: =INDEX($A:$A,MATCH(MIN(AT$2:AT$33),AT:AT,0)) -> Houston Texans | AU36: =INDEX($A:$A,MATCH(MIN(AU$2:AU$33),AU:AU,0)) -> Houston Texans | AV36: =INDEX($A:$A,MATCH(MAX(AV$2:AV$33),AV:AV,0)) -> New York Jets | AW36: =INDEX($A:$A,MATCH(MIN(AW$2:AW$33),AW:AW,0)) -> New York Jets | AX36: =INDEX($A:$A,MATCH(MIN(AX$2:AX$33),AX:AX,0)) -> New York Giants | AY36: =INDEX($A:$A,MATCH(MIN(AY$2:AY$33),AY:AY,0)) -> New York Giants | AZ36: =INDEX($A:$A,MATCH(MIN(AZ$2:AZ$33),AZ:AZ,0)) -> Houston Texans | BA36: =INDEX($A:$A,MATCH(MIN(BA$2:BA$33),BA:BA,0)) -> Houston Texans

Sheet By Division
A1: Teams | B1: NFC/AFC | C1: Division | D1: Total Wins | E1: Total Loses | F1: Total Wins @ Home | G1: Total Loses @ Home | H1: Total Wins Away | I1: Total Loses Away | J1: Total Points Scored | K1: Average Points | L1: Total Points Allowed | M1: Average Points Allowed | N1: Points Differential | O1: Average Points Differential | P1: Total Yards | Q1: Total Yards Allowed | R1: Average Yards | S1: Average Yards Allowed | T1: Yards Differential | U1: If Win, Points Scored | V1: If Win Average | W1: If Win, Opponent Scored | X1: If Win Opponent Average | Y1: Win Total Differential | Z1: Win Average Pts Differential | AA1: If Loss, Points Scored | AB1: If Loss, Points Average | AC1: If Loss, Opponent Scored | AD1: If Loss, Opponents Average | AE1: If Loss, Total Pts Differential | AF1: If Loss, Avg Pts Differential | AG1: Closet Win | AH1: Closest Loss | AI1: Biggest Win | AJ1: Biggest Loss | AK1: Most Points | AL1: Least Points | AM1: Most Yards | AN1: Least Yards | AO1: If Win, Average Yards | AP1: If Win, Average Opponents Yards | AQ1: Win, Avg Yards Differential | AR1: If Lose, Average Yards | AS1: If Lose, Average Opponents Yards | AT1: Lose, Yards Differential | AU1: Average Points @ Home | AV1: Average Yards @ Homes | AW1: Average Points Away | AX1: Average Yards Away
A2: Miami Dolphins | B2: AFC | C2: East | D2: =COUNTIF(Stats!F:F,A2) -> 9 | E2: =COUNTIF(Stats!H:H,A2) -> 8 | F2: =COUNTIFS(Stats!F:F,A2,Stats!E:E,"H") -> 6 | G2: =COUNTIFS(Stats!H:H,A2,Stats!G:G,"H") -> 3 | H2: =D2-F2 -> 3 | I2: =E2-G2 -> 5 | J2: =SUMIFS(Stats!I:I,Stats!F:F,A2)+SUMIFS(Stats!J:J,Stats!H:H,A2) -> 341 | K2: =J2/(D2+E2) -> 20.058824 | L2: =SUMIFS(Stats!I:I,Stats!H:H,A2)+SUMIFS(Stats!J:J,Stats!F:F,A2) -> 373 | M2: =L2/SUM(D2,E2) -> 21.941176 | N2: =J2-L2 -> -32 | O2: =N2/(D2+E2) -> -1.8823529 | P2: =SUMIFS(Stats!K:K,Stats!F:F,A2)+SUMIFS(Stats!M:M,Stats!H:H,A2) -> 5226 | Q2: =SUMIFS(Stats!K:K,Stats!H:H,A2)+SUMIFS(Stats!M:M,Stats!F:F,A2) -> 5738 | R2: =P2/(D2+E2) -> 307.41176 | S2: =Q2/(D2+E2) -> 337.52941 | T2: =P2-Q2 -> -512 | U2: =SUMIFS(Stats!I:I,Stats!F:F,A2) -> 217 | V2: =U2/D2 -> 24.111111 | W2: =SUMIFS(Stats!J:J,Stats!F:F,A2) -> 122 | X2: =W2/D2 -> 13.555556 | Y2: =U2-W2 -> 95 | Z2: =V2-X2 -> 10.555556 | AA2: =SUMIFS(Stats!J:J,Stats!H:H,A2) -> 124 | AB2: =AA2/E2 -> 15.5 | AC2: =SUMIFS(Stats!I:I,Stats!H:H,A2) -> 251 | AD2: =AC2/E2 -> 31.375 | AE2: =AA2-AC2 -> -127 | AF2: =AB2-AD2 -> -15.875 | AG2: =_xlfn.MINIFS(Stats!O:O,Stats!F:F,A2) -> 1 | AH2: =-_xlfn.MINIFS(Stats!O:O,Stats!H:H,A2) -> -2 | AI2: =_xlfn.MAXIFS(Stats!O:O,Stats!F:F,A2) -> 23 | AJ2: =-_xlfn.MAXIFS(Stats!O:O,Stats!H:H,A2) -> -35 | AK2: =_xlfn.MAXIFS(Stats!I:I,Stats!F:F,A2) -> 33 | AL2: =IF(_xlfn.MINIFS(Stats!I:I,Stats!F:F,A2)<_xlfn.MINIFS(Stats!J:J,Stats!H:H,A2),_xlfn.MINIFS(Stats!I:I,Stats!F:F,A2),_xlfn.MINIFS(Stats!J:J,Stats!H:H,A2)) -> 0 | AM2: =IF(_xlfn.MAXIFS(Stats!K:K,Stats!F:F,A2)>_xlfn.MAXIFS(Stats!M:M,Stats!H:H,A2),_xlfn.MAXIFS(Stats!K:K,Stats!F:F,A2),_xlfn.MAXIFS(Stats!M:M,Stats!H:H,A2)) -> 431 | AN2: =IF(_xlfn.MINIFS(Stats!M:M,Stats!H:H,A2)<_xlfn.MINIFS(Stats!K:K,Stats!F:F,A2),_xlfn.MINIFS(Stats!M:M,Stats!H:H,A2),_xlfn.MINIFS(Stats!K:K,Stats!F:F,A2)) -> 203 | AO2: =SUMIFS(Stats!K:K,Stats!F:F,A2)/D2 -> 311.88889 | AP2: =SUMIFS(Stats!M:M,Stats!F:F,A2)/D2 -> 285.33333 | AQ2: =AO2-AP2 -> 26.555556 | AR2: =SUMIFS(Stats!M:M,Stats!H:H,A2)/E2 -> 302.375 | AS2: =SUMIFS(Stats!K:K,Stats!H:H,A2)/E2 -> 396.25 | AT2: =AR2-AS2 -> -93.875 | AU2: =(SUMIFS(Stats!I:I,Stats!E:E,"H",Stats!F:F,A2)+SUMIFS(Stats!J:J,Stats!H:H,A2,Stats!G:G,"H"))/(F2+G2) -> 22.333333 | AV2: =(SUMIFS(Stats!K:K,Stats!F:F,A2,Stats!E:E,"H")+SUMIFS(Stats!M:M,Stats!G:G,"H",Stats!H:H,A2))/(F2+G2) -> 304.44444 | AW2: =(SUMIFS(Stats!I:I,Stats!E:E,"V",Stats!F:F,A2)+SUMIFS(Stats!J:J,Stats!H:H,A2,Stats!G:G,"V"))/(H2+I2) -> 17.5 | AX2: =(SUMIFS(Stats!K:K,Stats!F:F,A2,Stats!E:E,"V")+SUMIFS(Stats!M:M,Stats!G:G,"V",Stats!H:H,A2))/(H2+I2) -> 310.75
A3: Buffalo Bills | B3: AFC | C3: East | D3: =COUNTIF(Stats!F:F,A3) -> 12 | E3: =COUNTIF(Stats!H:H,A3) -> 7 | F3: =COUNTIFS(Stats!F:F,A3,Stats!E:E,"H") -> 7 | G3: =COUNTIFS(Stats!H:H,A3,Stats!G:G,"H") -> 3 | H3: =D3-F3 -> 5 | I3: =E3-G3 -> 4 | J3: =SUMIFS(Stats!I:I,Stats!F:F,A3)+SUMIFS(Stats!J:J,Stats!H:H,A3) -> 566 | K3: =J3/(D3+E3) -> 29.789474 | L3: =SUMIFS(Stats!I:I,Stats!H:H,A3)+SUMIFS(Stats!J:J,Stats!F:F,A3) -> 348 | M3: =L3/SUM(D3,E3) -> 18.315789 | N3: =J3-L3 -> 218 | O3: =N3/(D3+E3) -> 11.473684 | P3: =SUMIFS(Stats!K:K,Stats!F:F,A3)+SUMIFS(Stats!M:M,Stats!H:H,A3) -> 7397 | Q3: =SUMIFS(Stats!K:K,Stats!H:H,A3)+SUMIFS(Stats!M:M,Stats!F:F,A3) -> 5501 | R3: =P3/(D3+E3) -> 389.31579 | S3: =Q3/(D3+E3) -> 289.52632 | T3: =P3-Q3 -> 1896 | U3: =SUMIFS(Stats!I:I,Stats!F:F,A3) -> 425 | V3: =U3/D3 -> 35.416667 | W3: =SUMIFS(Stats!J:J,Stats!F:F,A3) -> 152 | X3: =W3/D3 -> 12.666667 | Y3: =U3-W3 -> 273 | Z3: =V3-X3 -> 22.75 | AA3: =SUMIFS(Stats!J:J,Stats!H:H,A3) -> 141 | AB3: =AA3/E3 -> 20.142857 | AC3: =SUMIFS(Stats!I:I,Stats!H:H,A3) -> 196 | AD3: =AC3/E3 -> 28 | AE3: =AA3-AC3 -> -55 | AF3: =AB3-AD3 -> -7.8571429 | AG3: =_xlfn.MINIFS(Stats!O:O,Stats!F:F,A3) -> 12 | AH3: =-_xlfn.MINIFS(Stats!O:O,Stats!H:H,A3) -> -3 | AI3: =_xlfn.MAXIFS(Stats!O:O,Stats!F:F,A3) -> 40 | AJ3: =-_xlfn.MAXIFS(Stats!O:O,Stats!H:H,A3) -> -26 | AK3: =_xlfn.MAXIFS(Stats!I:I,Stats!F:F,A3) -> 47 | AL3: =IF(_xlfn.MINIFS(Stats!I:I,Stats!F:F,A3)<_xlfn.MINIFS(Stats!J:J,Stats!H:H,A3),_xlfn.MINIFS(Stats!I:I,Stats!F:F,A3),_xlfn.MINIFS(Stats!J:J,Stats!H:H,A3)) -> 6 | AM3: =IF(_xlfn.MAXIFS(Stats!K:K,Stats!F:F,A3)>_xlfn.MAXIFS(Stats!M:M,Stats!H:H,A3),_xlfn.MAXIFS(Stats!K:K,Stats!F:F,A3),_xlfn.MAXIFS(Stats!M:M,Stats!H:H,A3)) -> 489 | AN3: =IF(_xlfn.MINIFS(Stats!M:M,Stats!H:H,A3)<_xlfn.MINIFS(Stats!K:K,Stats!F:F,A3),_xlfn.MINIFS(Stats!M:M,Stats!H:H,A3),_xlfn.MINIFS(Stats!K:K,Stats!F:F,A3)) -> 230 | AO3: =SUMIFS(Stats!K:K,Stats!F:F,A3)/D3 -> 406.58333 | AP3: =SUMIFS(Stats!M:M,Stats!F:F,A3)/D3 -> 251.5 | AQ3: =AO3-AP3 -> 155.08333 | AR3: =SUMIFS(Stats!M:M,Stats!H:H,A3)/E3 -> 359.71429 | AS3: =SUMIFS(Stats!K:K,Stats!H:H,A3)/E3 -> 354.71429 | AT3: =AR3-AS3 -> 5 | AU3: =(SUMIFS(Stats!I:I,Stats!E:E,"H",Stats!F:F,A3)+SUMIFS(Stats!J:J,Stats!H:H,A3,Stats!G:G,"H"))/(F3+G3) -> 28.4 | AV3: =(SUMIFS(Stats!K:K,Stats!F:F,A3,Stats!E:E,"H")+SUMIFS(Stats!M:M,Stats!G:G,"H",Stats!H:H,A3))/(F3+G3) -> 376.3 | AW3: =(SUMIFS(Stats!I:I,Stats!E:E,"V",Stats!F:F,A3)+SUMIFS(Stats!J:J,Stats!H:H,A3,Stats!G:G,"V"))/(H3+I3) -> 31.333333 | AX3: =(SUMIFS(Stats!K:K,Stats!F:F,A3,Stats!E:E,"V")+SUMIFS(Stats!M:M,Stats!G:G,"V",Stats!H:H,A3))/(H3+I3) -> 403.77778
